Workbook
Name AgnesLevelCurrent: 'Dawn Academy Alternate Layout'!$B$71
Name AgnesLevelCurrent: 'Dawn Academy'!$B$43
Name AgnesLevelDesired: 'Dawn Academy Alternate Layout'!$B$73
Name AgnesLevelDesired: 'Dawn Academy'!$B$45
Name AllSpeedupSecs: Lists!$A$100
Name ApeCurrent: Pets!$D$14
Name ApeDesired: Pets!$E$14
Name ApeFood: 'Pet Data'!$CG$27
Name ApeManuals: 'Pet Data'!$CI$27
Name ApePoints: 'Pet Data'!$CO$27
Name ApePotions: 'Pet Data'!$CK$27
Name ApeSerum: 'Pet Data'!$CM$27
Name ArenaEliteCurrent: 'Dawn Academy Alternate Layout'!$O$70
Name ArenaEliteCurrent: 'Dawn Academy'!$S$46
Name ArenaEliteDesired: 'Dawn Academy Alternate Layout'!$O$72
Name ArenaEliteDesired: 'Dawn Academy'!$S$48
Name ArenaStarCurrent: 'Dawn Academy Alternate Layout'!$S$70
Name ArenaStarCurrent: 'Dawn Academy'!$AA$46
Name ArenaStarDesired: 'Dawn Academy Alternate Layout'!$S$72
Name ArenaStarDesired: 'Dawn Academy'!$AA$48
Name BaldurLevelCurrent: 'Dawn Academy'!$B$71
Name BaldurLevelDesired: 'Dawn Academy'!$B$73
Name BarricadeCurrent: Construction!$D$38
Name BarricadeDays: Barricade!$Q$19
Name BarricadeDesired: Construction!$D$40
Name BarricadeHours: Barricade!$Q$20
Name BarricadeMinutes: Barricade!$Q$21
Name BarricadeSeconds: Barricade!$Q$22
Name BarricadeSecs: Barricade!$Q$17
Name BaseTier: 'Troop Calculator'!$E$14
Name BattleBulwarkCurrent: 'Dawn Academy'!$AE$68
Name BattleBulwarkDesired: 'Dawn Academy'!$AE$70
Name BlazingSunriseCurrent: 'Dawn Academy'!$S$79
Name BlazingSunriseDesired: 'Dawn Academy'!$S$81
Name BountyHunterCurrent: 'Dawn Academy'!$AA$79
Name BountyHunterDesired: 'Dawn Academy'!$AA$81
Name BuildersAide: Construction!$F$9
Name CallOfWarCurrent: 'Dawn Academy Alternate Layout'!$O$81
Name CallOfWarCurrent: 'Dawn Academy'!$S$57
Name CallOfWarDesired: 'Dawn Academy Alternate Layout'!$O$83
Name CallOfWarDesired: 'Dawn Academy'!$S$59
Name ChameleonCurrent: Pets!$D$19
Name ChameleonDesired: Pets!$E$19
Name ChameleonFood: 'Pet Data'!$EE$27
Name ChameleonManuals: 'Pet Data'!$EG$27
Name ChameleonPoints: 'Pet Data'!$EM$27
Name ChameleonPotions: 'Pet Data'!$EI$27
Name ChameleonSerum: 'Pet Data'!$EK$27
Name CoalCurrent: Construction!$F$38
Name CoalDays: 'Coal Mine'!$Q$39
Name CoalDesired: Construction!$F$40
Name CoalHours: 'Coal Mine'!$Q$40
Name CoalMineSecs: 'Coal Mine'!$Q$37
Name CoalMinutes: 'Coal Mine'!$Q$41
Name CoalSeconds: 'Coal Mine'!$Q$42
Name CoatCurrentLevel: 'Chief Gear & Charms'!$B$22
Name CoatDesiredLevel: 'Chief Gear & Charms'!$D$22
Name CoatLeftCurrentLevel: 'Chief Gear & Charms'!$C$26
Name CoatLeftDesiredLevel: 'Chief Gear & Charms'!$C$28
Name CoatRightCurrentLevel: 'Chief Gear & Charms'!$E$26

Sheet Construction
A1: Version | C1: 3.1b | E1: (631) Zerethusta's Whiteout Survival Calculator (RIP 631, now 646)
A2: Last Updated | C2: 45964
A4: Bonuses | H4: Resources | U4: How To Find Your Speedup Minutes
A5: What is your Construction Speed Percentage? | F5: 0.886 | H5: Meat | J5: Wood | L5: Coal | N5: Iron | P5: Fire Crystals | R5: Refined FC's
A6: Does your state have Supreme Presidency? | F6: Yes / No | H6: 5000000000 | J6: 5000000000 | L6: 1000000000 | N6: 500000000 | P6: 5000 | R6: 250
A7: Add Mercantilism 10% Bonus? | F7: Yes / No
A8: ="Add Vice President "&IF(SupremePresident="Yes",15,10)&"% Bonus?" -> Add Vice President 10% Bonus? | F8: Yes / No | H8: Only Input Data In The Orange Boxes. Don't Blame Me If You Put Info In Other Boxes And It No Longer Works. | P8: Speedups (in Minutes)
A9: Hyena Skill (Builder's Aide) % | F9: 0.15 | P9: General | R9: Construction
A10: Zinman's Middle Expedition Skill (Resourceful) % | F10: 0.15 | P10: 100000 | R10: 15000
H11: -Z | P11: =Lists!A59&"d "&Lists!A60&":"&Lists!A61&":"&Lists!A62 -> 69d 10:40:0 | R11: =Lists!A52&"d "&Lists!A53&":"&Lists!A54&":"&Lists!A62 -> 10d 10:0:0
A13: Construction Calculator (See other sheets for other calculators)
C16: Fire Crystal Buildings
C19: Furnace | E19: Comm. Ctr. | G19: Embassy | I19: Infirmary | K19: Infantry Camp | M19: Lancer Camp | O19: Marksman Camp | Q19: War Academy
C20: Current | E20: Current | G20: Current | I20: Current | K20: Current | M20: Current | O20: Current | Q20: Current
C21: FC8 | E21: FC8 | G21: FC8 | I21: FC8 | K21: FC8 | M21: FC8 | O21: FC8 | Q21: FC5
C22: Desired | E22: Desired | G22: Desired | I22: Desired | K22: Desired | M22: Desired | O22: Desired | Q22: Desired
C23: FC9 | E23: FC9 | G23: FC9 | K23: FC9 | M23: FC9 | O23: FC9
C24: =C23&" Furnace Needs ->" -> FC9 Furnace Needs -> | E24: =VLOOKUP($C$23,Furnace!$B$5:$AI$85,23,FALSE) -> 1 | G24: =VLOOKUP($C$23,Furnace!$B$5:$AI$85,25,FALSE) -> FC8 | I24: =VLOOKUP($C$23,Furnace!$B$5:$AI$85,28,FALSE) -> 1 | K24: =VLOOKUP($C$23,Furnace!$B$5:$AI$85,27,FALSE) -> FC8 | M24: =VLOOKUP($C$23,Furnace!$B$5:$AI$85,30,FALSE) -> FC7 | O24: =VLOOKUP($C$23,Furnace!$B$5:$AI$85,31,FALSE) -> FC6 | Q24: -
B25: Meat | C25: =IFERROR(Furnace!$E$87*(1-Zinman),0) -> 595000000 | E25: =IFERROR('Command Center'!$E$87*(1-Zinman),0) -> 182750000 | G25: =IFERROR(Embassy!$E$87*(1-Zinman),0) -> 123250000 | I25: =IFERROR(Infirmary!$E$87*(1-Zinman),0) -> 0 | K25: =IFERROR('Infantry Camp'!$E$87*(1-Zinman),0) -> 212500000 | M25: =IFERROR('Lancer Camp'!$E$87*(1-Zinman),0) -> 212500000 | O25: =IFERROR('Marksman Camp'!$E$87*(1-Zinman),0) -> 212500000 | Q25: =IFERROR('War Academy'!E53*(1-Zinman),0) -> 0 | S25: Meat
B26: Wood | C26: =IFERROR(Furnace!G87*(1-Zinman),0) -> 595000000 | E26: =IFERROR('Command Center'!G87*(1-Zinman),0) -> 182750000 | G26: =IFERROR(Embassy!G87*(1-Zinman),0) -> 123250000 | I26: =IFERROR(Infirmary!G87*(1-Zinman),0) -> 0 | K26: =IFERROR('Infantry Camp'!G87*(1-Zinman),0) -> 212500000 | M26: =IFERROR('Lancer Camp'!G87*(1-Zinman),0) -> 212500000 | O26: =IFERROR('Marksman Camp'!G87*(1-Zinman),0) -> 212500000 | Q26: =IFERROR('War Academy'!G53*(1-Zinman),0) -> 0 | S26: Wood
B27: Coal | C27: =IFERROR(Furnace!I87*(1-Zinman),0) -> 123250000 | E27: =IFERROR('Command Center'!I87*(1-Zinman),0) -> 36975000 | G27: =IFERROR(Embassy!I87*(1-Zinman),0) -> 24650000 | I27: =IFERROR(Infirmary!I87*(1-Zinman),0) -> 0 | K27: =IFERROR('Infantry Camp'!I87*(1-Zinman),0) -> 42500000 | M27: =IFERROR('Lancer Camp'!I87*(1-Zinman),0) -> 42500000 | O27: =IFERROR('Marksman Camp'!I87*(1-Zinman),0) -> 42500000 | Q27: =IFERROR('War Academy'!I53*(1-Zinman),0) -> 0 | S27: Coal
B28: Iron | C28: =IFERROR(Furnace!K87*(1-Zinman),0) -> 30600000 | E28: =IFERROR('Command Center'!K87*(1-Zinman),0) -> 8925000 | G28: =IFERROR(Embassy!K87*(1-Zinman),0) -> 5950000 | I28: =IFERROR(Infirmary!K87*(1-Zinman),0) -> 0 | K28: =IFERROR('Infantry Camp'!K87*(1-Zinman),0) -> 10625000 | M28: =IFERROR('Lancer Camp'!K87*(1-Zinman),0) -> 10625000 | O28: =IFERROR('Marksman Camp'!K87*(1-Zinman),0) -> 10625000 | Q28: =IFERROR('War Academy'!K53*(1-Zinman),0) -> 0 | S28: Iron
B29: Fire Crystals | C29: =IFERROR(Furnace!M87,0) -> 1400 | E29: =IFERROR('Command Center'!M87,0) -> 252 | G29: =IFERROR(Embassy!M87,0) -> 315 | I29: =IFERROR(Infirmary!M87,0) -> 0 | K29: =IFERROR('Infantry Camp'!M87,0) -> 567 | M29: =IFERROR('Lancer Camp'!M87,0) -> 567 | O29: =IFERROR('Marksman Camp'!M87,0) -> 567 | Q29: =IFERROR('War Academy'!M53,0) -> 0 | S29: FC's | V29: Construction Time
B30: Refined FCs | C30: =IFERROR(Furnace!O87,0) -> 180 | E30: =IFERROR('Command Center'!O87,0) -> 36 | G30: =IFERROR(Embassy!O87,0) -> 43 | I30: =IFERROR(Infirmary!O87,0) -> 0 | K30: =IFERROR('Infantry Camp'!O87,0) -> 79 | M30: =IFERROR('Lancer Camp'!O87,0) -> 79 | O30: =IFERROR('Marksman Camp'!O87,0) -> 79 | Q30: =IFERROR('War Academy'!O53,0) -> 0 | S30: Refined | V30: Raw Time Unadjusted
B31: Unboosted Time | C31: =IFERROR(FurnaceDays&"d "&FurnaceHours&":"&FurnaceMinutes&":"&FurnaceSeconds,"0d 0:0:0") -> 65d 0:0:0 | E31: =IFERROR(CommCtrDays&"d "&CommCtrHours&":"&CommCtrMinutes&":"&CommCtrSeconds,"0d 0:0:0") -> 7d 19:10:0 | G31: =IFERROR(EmbassyDays&"d "&EmbassyHours&":"&EmbassyMinutes&":"&EmbassySeconds,"0d 0:0:0") -> 42d 21:35:0 | I31: =IFERROR(InfirmaryDays&"d "&InfirmaryHours&":"&InfirmaryMinutes&":"&InfirmarySeconds,"0d 0:0:0") -> 0d 0:0:0 | K31: =IFERROR(InfantryDays&"d "&InfantryHours&":"&InfantryMinutes&":"&InfantrySeconds,"0d 0:0:0") -> 9d 18:0:0 | M31: =IFERROR(LancerDays&"d "&LancerHours&":"&LancerMinutes&":"&LancerSeconds,"0d 0:0:0") -> 9d 18:0:0 | O31: =IFERROR(MarksmanDays&"d "&MarksmanHours&":"&MarksmanMinutes&":"&MarksmanSeconds,"0d 0:0:0") -> 9d 18:0:0 | Q31: =IFERROR(WarAcademyDays&"d "&WarAcademyHours&":"&WarAcademyMinutes&":"&WarAcademySeconds,"0d 0:0:0") -> 0d 0:0:0 | V31: =IFERROR(TotalDays&"d "&TotalHours&":"&TotalMinutes&":"&TotalSeconds,0) -> 0
V32: Adjusted Time (Mercantilism, VP, Double Time, & Builder's Aide)
D33: Other Buildings
V34: =IFERROR(DTBADays&"d "&DTBAHours&":"&DTBAMinutes&":"&DTBASeconds,0) -> 0
V35: Construction & General Speedups Available
D36: Barricade | F36: Coal Mine | H36: Hunter's Hut | J36: Iron Mine | L36: Research Ctr. | N36: Sawmill | P36: Shelter
D37: Current | F37: Current | H37: Current | J37: Current | L37: Current | N37: Current | P37: Current | V37: =IFERROR(Lists!A66&"d "&Lists!A67&":"&Lists!A68&":"&Lists!A69,0) -> 79d 20:40:0
D38: 10 | F38: 30 | H38: 30 | J38: 30 | L38: 30 | N38: 30 | P38: 10
D39: Desired | F39: Desired | H39: Desired | J39: Desired | L39: Desired | N39: Desired | P39: Desired | V39: Total Resource Cost | X39: Resources Available | Z39: Resources Needed | AB39: SVS Points
D41: =$C$23&" Furnace Needs ->" -> FC9 Furnace Needs -> | F41: 3 | H41: =VLOOKUP($C$23,Furnace!$B$5:$AI$85,26,FALSE) -> 6 | J41: =VLOOKUP($C$23,Furnace!$B$5:$AI$85,29,FALSE) -> 5 | L41: =VLOOKUP($C$23,Furnace!$B$5:$AI$85,32,FALSE) -> 30 | N41: =VLOOKUP($C$23,Furnace!$B$5:$AI$85,33,FALSE) -> 1 | P41: =VLOOKUP($C$23,Furnace!$B$5:$AI$85,34,FALSE) -> 3 | U41: Meat | V41: =SUM(C25:R25)+SUM(D42:Q42) -> 1538500000 | X41: =H6 -> 5000000000 | Z41: =IF(V41-X41>0,V41-X41,"-") -> - | AD41: Meat
C42: Meat | D42: =Barricade!$D$17*(1-Zinman) -> 0 | F42: ='Coal Mine'!$D$37*(1-Zinman) -> 0 | H42: ='Hunter''s Hut'!$D$37*(1-Zinman) -> 0 | J42: ='Iron Mine'!$D$37*(1-Zinman) -> 0 | L42: ='Research Center'!$D$37*(1-Zinman) -> 0 | N42: =Sawmill!$D$37*(1-Zinman) -> 0 | P42: =Shelter!$D$17*(1-Zinman) -> 0 | R42: Meat | U42: Wood | V42: =SUM(C26:R26)+SUM(D43:Q43) -> 1538500000 | X42: =J6 -> 5000000000 | Z42: =IF(V42-X42>0,V42-X42,"-") -> - | AD42: Wood
C43: Wood | D43: =Barricade!F17*(1-Zinman) -> 0 | F43: ='Coal Mine'!$F$37*(1-Zinman) -> 0 | H43: ='Hunter''s Hut'!$F$37*(1-Zinman) -> 0 | J43: ='Iron Mine'!$F$37*(1-Zinman) -> 0 | L43: ='Research Center'!$F$37*(1-Zinman) -> 0 | N43: =Sawmill!$F$37*(1-Zinman) -> 0 | P43: =Shelter!$F$17*(1-Zinman) -> 0 | R43: Wood | U43: Coal | V43: =SUM(C27:R27)+SUM(D44:Q44) -> 312375000 | X43: =L6 -> 1000000000 | Z43: =IF(V43-X43>0,V43-X43,"-") -> - | AD43: Coal
C44: Coal | D44: =Barricade!H17*(1-Zinman) -> 0 | F44: ='Coal Mine'!$H$37*(1-Zinman) -> 0 | H44: ='Hunter''s Hut'!$H$37*(1-Zinman) -> 0 | J44: ='Iron Mine'!$H$37*(1-Zinman) -> 0 | L44: ='Research Center'!$H$37*(1-Zinman) -> 0 | N44: =Sawmill!$H$37*(1-Zinman) -> 0 | P44: =Shelter!$H$17*(1-Zinman) -> 0 | R44: Coal | U44: Iron | V44: =SUM(C28:R28)+SUM(D45:Q45) -> 77350000 | X44: =N6 -> 500000000 | Z44: =IF(V44-X44>0,V44-X44,"-") -> - | AD44: Iron
C45: Iron | D45: =Barricade!J17*(1-Zinman) -> 0 | F45: ='Coal Mine'!$J$37*(1-Zinman) -> 0 | H45: ='Hunter''s Hut'!$J$37*(1-Zinman) -> 0 | J45: ='Iron Mine'!$J$37*(1-Zinman) -> 0 | L45: ='Research Center'!$J$37*(1-Zinman) -> 0 | N45: =Sawmill!$J$37*(1-Zinman) -> 0 | P45: =Shelter!$J$17*(1-Zinman) -> 0 | R45: Iron | U45: FC | V45: =SUM(C29:R29) -> 3668 | X45: =P6 -> 5000 | Z45: =IF(V45-X45>0,V45-X45,"-") -> - | AB45: =V45*2000 -> 7336000 | AD45: FC
C46: Unboosted Time | D46: =BarricadeDays&"d "&BarricadeDays&":"&BarricadeMinutes&":"&BarricadeSeconds -> 0d 0:0:0 | F46: =CoalDays&"d "&CoalHours&":"&CoalMinutes&":"&CoalSeconds -> 0d 0:0:0 | H46: =HuntersHutDays&"d "&HuntersHutHours&":"&HuntersHutMinutes&":"&HuntersHutSeconds -> 0d 0:0:0 | J46: =IronDays&"d "&IronHours&":"&IronMinutes&":"&IronSeconds -> 0d 0:0:0 | L46: =ResearchDays&"d "&ResearchHours&":"&ResearchMinutes&":"&ResearchMinutes -> 0d 0:0:0 | N46: =SawmillDays&"d "&SawmillHours&":"&SawmillMinutes&":"&SawmillSeconds -> 0d 0:0:0 | P46: =ShelterDays&"d "&ShelterHours&":"&ShelterMinutes&":"&ShelterSeconds -> 0d 0:0:0 | R46: Unboosted Time | U46: Refined FC | V46: =SUM(C30:R30) -> 496 | X46: =R6 -> 250 | Z46: =IF(V46-X46>0,V46-X46,"-") -> 246 | AB46: =V46*30000 -> 14880000 | AD46: Refined FC
U47: Time Cost | V47: =IFERROR(DTBADays&"d "&DTBAHours&":"&DTBAMinutes&":"&DTBASeconds,"0d 0:0:0") -> 0d 0:0:0 | X47: =Lists!A66&"d "&Lists!A67&":"&Lists!A68&":"&Lists!A69 -> 79d 20:40:0 | Z47: =IFERROR(IF(NeededSpeedupSecs>0,Lists!A73&"d "&Lists!A74&":"&Lists!A75&":"&Lists!A76,"-"),"0d 0:0:0") -> 0d 0:0:0 | AB47: =IFERROR(DTBASecs/60*30,0) -> 0 | AD47: <- May be lower based on # of helps, or if not using speedups for all builds
...

Sheet Furnace
B2: 1 | C2: 2 | D2: 3 | E2: 4 | F2: 5 | G2: 6 | H2: 7 | I2: 8 | J2: 9 | K2: 10 | L2: 11 | M2: 12 | N2: 13 | O2: 14 | P2: 15 | Q2: 16 | R2: 17 | S2: 18 | T2: 19 | U2: 20 | V2: 21 | W2: 22 | X2: 23 | Y2: 24 | Z2: 25 | AA2: 26 | AB2: 27 | AC2: 28 | AD2: 29 | AE2: 30 | AF2: 31 | AG2: 32 | AH2: 33 | AI2: 34
B3: Furnace | D3: Resource Cost | Q3: Building Time | X3: Preqrequisite Levels
B4: =#REF! -> #REF! | D4: Meat | F4: Wood | H4: Coal | J4: Iron | L4: Fire Crystals | N4: Refined FCs | U4: Seconds | X4: Command Center | Y4: Coal Mine | Z4: Embassy | AA4: Hunter's Hut | AB4: Infantry Camp | AC4: Infirmary | AD4: Iron Mine | AE4: Lancer Camp | AF4: Marksman Camp | AG4: Research Center | AH4: Sawmill | AI4: Shelter
B5: 0 | C5: Numerical | D5: Total | E5: Remaining | F5: Total | G5: Remaining | H5: Total | I5: Remaining | J5: Total | K5: Remaining | L5: Total | M5: Remaining | N5: Total | O5: Remaining | Q5: Days | R5: Hours | S5: Minutes | T5: Seconds | U5: Total | V5: Remaining
B6: 1 | C6: 1 | E6: =IF($C6>VLOOKUP(FurnaceDesired,$B$6:$C$85,2,FALSE),"",IF($C6>VLOOKUP(FurnaceCurrent,$B$6:$C$85,2,FALSE),D6,"")) | G6: =IF($C6>VLOOKUP(FurnaceDesired,$B$6:$C$85,2,FALSE),"",IF($C6>VLOOKUP(FurnaceCurrent,$B$6:$C$85,2,FALSE),F6,"")) | I6: =IF($C6>VLOOKUP(FurnaceDesired,$B$6:$C$85,2,FALSE),"",IF($C6>VLOOKUP(FurnaceCurrent,$B$6:$C$85,2,FALSE),H6,"")) | K6: =IF($C6>VLOOKUP(FurnaceDesired,$B$6:$C$85,2,FALSE),"",IF($C6>VLOOKUP(FurnaceCurrent,$B$6:$C$85,2,FALSE),J6,"")) | M6: =IF($C6>VLOOKUP(FurnaceDesired,$B$6:$C$85,2,FALSE),"",IF($C6>VLOOKUP(FurnaceCurrent,$B$6:$C$85,2,FALSE),L6,"")) | O6: =IF($C6>VLOOKUP(FurnaceDesired,$B$6:$C$85,2,FALSE),"",IF($C6>VLOOKUP(FurnaceCurrent,$B$6:$C$85,2,FALSE),N6,"")) | U6: =T6+S6*60+R6*60*60+Q6*60*60*24 -> 0 | V6: =IF($C6>VLOOKUP(FurnaceDesired,$B$6:$C$85,2,FALSE),"",IF($C6>VLOOKUP(FurnaceCurrent,$B$6:$C$85,2,FALSE),U6,"")) | X6: - | Y6: - | Z6: - | AA6: - | AB6: - | AC6: - | AD6: - | AE6: - | AF6: - | AG6: - | AH6: - | AI6: -
B7: 2 | C7: 2 | E7: =IF($C7>VLOOKUP(FurnaceDesired,$B$6:$C$85,2,FALSE),"",IF($C7>VLOOKUP(FurnaceCurrent,$B$6:$C$85,2,FALSE),D7,"")) | F7: 180 | G7: =IF($C7>VLOOKUP(FurnaceDesired,$B$6:$C$85,2,FALSE),"",IF($C7>VLOOKUP(FurnaceCurrent,$B$6:$C$85,2,FALSE),F7,"")) | I7: =IF($C7>VLOOKUP(FurnaceDesired,$B$6:$C$85,2,FALSE),"",IF($C7>VLOOKUP(FurnaceCurrent,$B$6:$C$85,2,FALSE),H7,"")) | K7: =IF($C7>VLOOKUP(FurnaceDesired,$B$6:$C$85,2,FALSE),"",IF($C7>VLOOKUP(FurnaceCurrent,$B$6:$C$85,2,FALSE),J7,"")) | M7: =IF($C7>VLOOKUP(FurnaceDesired,$B$6:$C$85,2,FALSE),"",IF($C7>VLOOKUP(FurnaceCurrent,$B$6:$C$85,2,FALSE),L7,"")) | O7: =IF($C7>VLOOKUP(FurnaceDesired,$B$6:$C$85,2,FALSE),"",IF($C7>VLOOKUP(FurnaceCurrent,$B$6:$C$85,2,FALSE),N7,"")) | T7: 6 | U7: =T7+S7*60+R7*60*60+Q7*60*60*24 -> 6 | V7: =IF($C7>VLOOKUP(FurnaceDesired,$B$6:$C$85,2,FALSE),"",IF($C7>VLOOKUP(FurnaceCurrent,$B$6:$C$85,2,FALSE),U7,"")) | X7: - | Y7: - | Z7: - | AA7: - | AB7: - | AC7: - | AD7: - | AE7: - | AF7: - | AG7: - | AH7: 1 | AI7: -
B8: 3 | C8: 3 | E8: =IF($C8>VLOOKUP(FurnaceDesired,$B$6:$C$85,2,FALSE),"",IF($C8>VLOOKUP(FurnaceCurrent,$B$6:$C$85,2,FALSE),D8,"")) | F8: 805 | G8: =IF($C8>VLOOKUP(FurnaceDesired,$B$6:$C$85,2,FALSE),"",IF($C8>VLOOKUP(FurnaceCurrent,$B$6:$C$85,2,FALSE),F8,"")) | I8: =IF($C8>VLOOKUP(FurnaceDesired,$B$6:$C$85,2,FALSE),"",IF($C8>VLOOKUP(FurnaceCurrent,$B$6:$C$85,2,FALSE),H8,"")) | K8: =IF($C8>VLOOKUP(FurnaceDesired,$B$6:$C$85,2,FALSE),"",IF($C8>VLOOKUP(FurnaceCurrent,$B$6:$C$85,2,FALSE),J8,"")) | M8: =IF($C8>VLOOKUP(FurnaceDesired,$B$6:$C$85,2,FALSE),"",IF($C8>VLOOKUP(FurnaceCurrent,$B$6:$C$85,2,FALSE),L8,"")) | O8: =IF($C8>VLOOKUP(FurnaceDesired,$B$6:$C$85,2,FALSE),"",IF($C8>VLOOKUP(FurnaceCurrent,$B$6:$C$85,2,FALSE),N8,"")) | S8: 1 | U8: =T8+S8*60+R8*60*60+Q8*60*60*24 -> 60 | V8: =IF($C8>VLOOKUP(FurnaceDesired,$B$6:$C$85,2,FALSE),"",IF($C8>VLOOKUP(FurnaceCurrent,$B$6:$C$85,2,FALSE),U8,"")) | X8: - | Y8: - | Z8: - | AA8: - | AB8: - | AC8: - | AD8: - | AE8: - | AF8: - | AG8: - | AH8: 1 | AI8: 2
B9: 4 | C9: 4 | E9: =IF($C9>VLOOKUP(FurnaceDesired,$B$6:$C$85,2,FALSE),"",IF($C9>VLOOKUP(FurnaceCurrent,$B$6:$C$85,2,FALSE),D9,"")) | F9: 1800 | G9: =IF($C9>VLOOKUP(FurnaceDesired,$B$6:$C$85,2,FALSE),"",IF($C9>VLOOKUP(FurnaceCurrent,$B$6:$C$85,2,FALSE),F9,"")) | H9: 360 | I9: =IF($C9>VLOOKUP(FurnaceDesired,$B$6:$C$85,2,FALSE),"",IF($C9>VLOOKUP(FurnaceCurrent,$B$6:$C$85,2,FALSE),H9,"")) | K9: =IF($C9>VLOOKUP(FurnaceDesired,$B$6:$C$85,2,FALSE),"",IF($C9>VLOOKUP(FurnaceCurrent,$B$6:$C$85,2,FALSE),J9,"")) | M9: =IF($C9>VLOOKUP(FurnaceDesired,$B$6:$C$85,2,FALSE),"",IF($C9>VLOOKUP(FurnaceCurrent,$B$6:$C$85,2,FALSE),L9,"")) | O9: =IF($C9>VLOOKUP(FurnaceDesired,$B$6:$C$85,2,FALSE),"",IF($C9>VLOOKUP(FurnaceCurrent,$B$6:$C$85,2,FALSE),N9,"")) | S9: 3 | U9: =T9+S9*60+R9*60*60+Q9*60*60*24 -> 180 | V9: =IF($C9>VLOOKUP(FurnaceDesired,$B$6:$C$85,2,FALSE),"",IF($C9>VLOOKUP(FurnaceCurrent,$B$6:$C$85,2,FALSE),U9,"")) | X9: - | Y9: 3 | Z9: - | AA9: - | AB9: - | AC9: - | AD9: - | AE9: - | AF9: - | AG9: - | AH9: 1 | AI9: 2
B10: 5 | C10: 5 | E10: =IF($C10>VLOOKUP(FurnaceDesired,$B$6:$C$85,2,FALSE),"",IF($C10>VLOOKUP(FurnaceCurrent,$B$6:$C$85,2,FALSE),D10,"")) | F10: 7600 | G10: =IF($C10>VLOOKUP(FurnaceDesired,$B$6:$C$85,2,FALSE),"",IF($C10>VLOOKUP(FurnaceCurrent,$B$6:$C$85,2,FALSE),F10,"")) | H10: 1500 | I10: =IF($C10>VLOOKUP(FurnaceDesired,$B$6:$C$85,2,FALSE),"",IF($C10>VLOOKUP(FurnaceCurrent,$B$6:$C$85,2,FALSE),H10,"")) | K10: =IF($C10>VLOOKUP(FurnaceDesired,$B$6:$C$85,2,FALSE),"",IF($C10>VLOOKUP(FurnaceCurrent,$B$6:$C$85,2,FALSE),J10,"")) | M10: =IF($C10>VLOOKUP(FurnaceDesired,$B$6:$C$85,2,FALSE),"",IF($C10>VLOOKUP(FurnaceCurrent,$B$6:$C$85,2,FALSE),L10,"")) | O10: =IF($C10>VLOOKUP(FurnaceDesired,$B$6:$C$85,2,FALSE),"",IF($C10>VLOOKUP(FurnaceCurrent,$B$6:$C$85,2,FALSE),N10,"")) | S10: 10 | U10: =T10+S10*60+R10*60*60+Q10*60*60*24 -> 600 | V10: =IF($C10>VLOOKUP(FurnaceDesired,$B$6:$C$85,2,FALSE),"",IF($C10>VLOOKUP(FurnaceCurrent,$B$6:$C$85,2,FALSE),U10,"")) | X10: - | Y10: 3 | Z10: - | AA10: - | AB10: - | AC10: - | AD10: - | AE10: - | AF10: - | AG10: - | AH10: 1 | AI10: 3
B11: 6 | C11: 6 | E11: =IF($C11>VLOOKUP(FurnaceDesired,$B$6:$C$85,2,FALSE),"",IF($C11>VLOOKUP(FurnaceCurrent,$B$6:$C$85,2,FALSE),D11,"")) | F11: 19000 | G11: =IF($C11>VLOOKUP(FurnaceDesired,$B$6:$C$85,2,FALSE),"",IF($C11>VLOOKUP(FurnaceCurrent,$B$6:$C$85,2,FALSE),F11,"")) | H11: 3800 | I11: =IF($C11>VLOOKUP(FurnaceDesired,$B$6:$C$85,2,FALSE),"",IF($C11>VLOOKUP(FurnaceCurrent,$B$6:$C$85,2,FALSE),H11,"")) | J11: 960 | K11: =IF($C11>VLOOKUP(FurnaceDesired,$B$6:$C$85,2,FALSE),"",IF($C11>VLOOKUP(FurnaceCurrent,$B$6:$C$85,2,FALSE),J11,"")) | M11: =IF($C11>VLOOKUP(FurnaceDesired,$B$6:$C$85,2,FALSE),"",IF($C11>VLOOKUP(FurnaceCurrent,$B$6:$C$85,2,FALSE),L11,"")) | O11: =IF($C11>VLOOKUP(FurnaceDesired,$B$6:$C$85,2,FALSE),"",IF($C11>VLOOKUP(FurnaceCurrent,$B$6:$C$85,2,FALSE),N11,"")) | S11: 30 | U11: =T11+S11*60+R11*60*60+Q11*60*60*24 -> 1800 | V11: =IF($C11>VLOOKUP(FurnaceDesired,$B$6:$C$85,2,FALSE),"",IF($C11>VLOOKUP(FurnaceCurrent,$B$6:$C$85,2,FALSE),U11,"")) | X11: - | Y11: 3 | Z11: - | AA11: - | AB11: - | AC11: - | AD11: 5 | AE11: - | AF11: - | AG11: - | AH11: 1 | AI11: 3
B12: 7 | C12: 7 | E12: =IF($C12>VLOOKUP(FurnaceDesired,$B$6:$C$85,2,FALSE),"",IF($C12>VLOOKUP(FurnaceCurrent,$B$6:$C$85,2,FALSE),D12,"")) | F12: 69000 | G12: =IF($C12>VLOOKUP(FurnaceDesired,$B$6:$C$85,2,FALSE),"",IF($C12>VLOOKUP(FurnaceCurrent,$B$6:$C$85,2,FALSE),F12,"")) | H12: 13000 | I12: =IF($C12>VLOOKUP(FurnaceDesired,$B$6:$C$85,2,FALSE),"",IF($C12>VLOOKUP(FurnaceCurrent,$B$6:$C$85,2,FALSE),H12,"")) | J12: 3400 | K12: =IF($C12>VLOOKUP(FurnaceDesired,$B$6:$C$85,2,FALSE),"",IF($C12>VLOOKUP(FurnaceCurrent,$B$6:$C$85,2,FALSE),J12,"")) | M12: =IF($C12>VLOOKUP(FurnaceDesired,$B$6:$C$85,2,FALSE),"",IF($C12>VLOOKUP(FurnaceCurrent,$B$6:$C$85,2,FALSE),L12,"")) | O12: =IF($C12>VLOOKUP(FurnaceDesired,$B$6:$C$85,2,FALSE),"",IF($C12>VLOOKUP(FurnaceCurrent,$B$6:$C$85,2,FALSE),N12,"")) | R12: 1 | U12: =T12+S12*60+R12*60*60+Q12*60*60*24 -> 3600 | V12: =IF($C12>VLOOKUP(FurnaceDesired,$B$6:$C$85,2,FALSE),"",IF($C12>VLOOKUP(FurnaceCurrent,$B$6:$C$85,2,FALSE),U12,"")) | X12: - | Y12: 3 | Z12: - | AA12: 6 | AB12: - | AC12: - | AD12: 5 | AE12: - | AF12: - | AG12: - | AH12: 1 | AI12: 3
B13: 8 | C13: 8 | E13: =IF($C13>VLOOKUP(FurnaceDesired,$B$6:$C$85,2,FALSE),"",IF($C13>VLOOKUP(FurnaceCurrent,$B$6:$C$85,2,FALSE),D13,"")) | F13: 120000 | G13: =IF($C13>VLOOKUP(FurnaceDesired,$B$6:$C$85,2,FALSE),"",IF($C13>VLOOKUP(FurnaceCurrent,$B$6:$C$85,2,FALSE),F13,"")) | H13: 25000 | I13: =IF($C13>VLOOKUP(FurnaceDesired,$B$6:$C$85,2,FALSE),"",IF($C13>VLOOKUP(FurnaceCurrent,$B$6:$C$85,2,FALSE),H13,"")) | J13: 6300 | K13: =IF($C13>VLOOKUP(FurnaceDesired,$B$6:$C$85,2,FALSE),"",IF($C13>VLOOKUP(FurnaceCurrent,$B$6:$C$85,2,FALSE),J13,"")) | M13: =IF($C13>VLOOKUP(FurnaceDesired,$B$6:$C$85,2,FALSE),"",IF($C13>VLOOKUP(FurnaceCurrent,$B$6:$C$85,2,FALSE),L13,"")) | O13: =IF($C13>VLOOKUP(FurnaceDesired,$B$6:$C$85,2,FALSE),"",IF($C13>VLOOKUP(FurnaceCurrent,$B$6:$C$85,2,FALSE),N13,"")) | R13: 2 | S13: 30 | U13: =T13+S13*60+R13*60*60+Q13*60*60*24 -> 9000 | V13: =IF($C13>VLOOKUP(FurnaceDesired,$B$6:$C$85,2,FALSE),"",IF($C13>VLOOKUP(FurnaceCurrent,$B$6:$C$85,2,FALSE),U13,"")) | X13: - | Y13: 3 | Z13: - | AA13: 6 | AB13: 7 | AC13: - | AD13: 5 | AE13: - | AF13: - | AG13: - | AH13: 1 | AI13: 3
B14: 9 | C14: 9 | E14: =IF($C14>VLOOKUP(FurnaceDesired,$B$6:$C$85,2,FALSE),"",IF($C14>VLOOKUP(FurnaceCurrent,$B$6:$C$85,2,FALSE),D14,"")) | F14: 260000 | G14: =IF($C14>VLOOKUP(FurnaceDesired,$B$6:$C$85,2,FALSE),"",IF($C14>VLOOKUP(FurnaceCurrent,$B$6:$C$85,2,FALSE),F14,"")) | H14: 52000 | I14: =IF($C14>VLOOKUP(FurnaceDesired,$B$6:$C$85,2,FALSE),"",IF($C14>VLOOKUP(FurnaceCurrent,$B$6:$C$85,2,FALSE),H14,"")) | J14: 13000 | K14: =IF($C14>VLOOKUP(FurnaceDesired,$B$6:$C$85,2,FALSE),"",IF($C14>VLOOKUP(FurnaceCurrent,$B$6:$C$85,2,FALSE),J14,"")) | M14: =IF($C14>VLOOKUP(FurnaceDesired,$B$6:$C$85,2,FALSE),"",IF($C14>VLOOKUP(FurnaceCurrent,$B$6:$C$85,2,FALSE),L14,"")) | O14: =IF($C14>VLOOKUP(FurnaceDesired,$B$6:$C$85,2,FALSE),"",IF($C14>VLOOKUP(FurnaceCurrent,$B$6:$C$85,2,FALSE),N14,"")) | R14: 4 | S14: 30 | U14: =T14+S14*60+R14*60*60+Q14*60*60*24 -> 16200 | V14: =IF($C14>VLOOKUP(FurnaceDesired,$B$6:$C$85,2,FALSE),"",IF($C14>VLOOKUP(FurnaceCurrent,$B$6:$C$85,2,FALSE),U14,"")) | X14: - | Y14: 3 | Z14: 8 | AA14: 6 | AB14: 7 | AC14: 1 | AD14: 5 | AE14: - | AF14: - | AG14: - | AH14: 1 | AI14: 3
B15: 10 | C15: 10 | E15: =IF($C15>VLOOKUP(FurnaceDesired,$B$6:$C$85,2,FALSE),"",IF($C15>VLOOKUP(FurnaceCurrent,$B$6:$C$85,2,FALSE),D15,"")) | F15: 460000 | G15: =IF($C15>VLOOKUP(FurnaceDesired,$B$6:$C$85,2,FALSE),"",IF($C15>VLOOKUP(FurnaceCurrent,$B$6:$C$85,2,FALSE),F15,"")) | H15: 92000 | I15: =IF($C15>VLOOKUP(FurnaceDesired,$B$6:$C$85,2,FALSE),"",IF($C15>VLOOKUP(FurnaceCurrent,$B$6:$C$85,2,FALSE),H15,"")) | J15: 23000 | K15: =IF($C15>VLOOKUP(FurnaceDesired,$B$6:$C$85,2,FALSE),"",IF($C15>VLOOKUP(FurnaceCurrent,$B$6:$C$85,2,FALSE),J15,"")) | M15: =IF($C15>VLOOKUP(FurnaceDesired,$B$6:$C$85,2,FALSE),"",IF($C15>VLOOKUP(FurnaceCurrent,$B$6:$C$85,2,FALSE),L15,"")) | O15: =IF($C15>VLOOKUP(FurnaceDesired,$B$6:$C$85,2,FALSE),"",IF($C15>VLOOKUP(FurnaceCurrent,$B$6:$C$85,2,FALSE),N15,"")) | R15: 6 | U15: =T15+S15*60+R15*60*60+Q15*60*60*24 -> 21600 | V15: =IF($C15>VLOOKUP(FurnaceDesired,$B$6:$C$85,2,FALSE),"",IF($C15>VLOOKUP(FurnaceCurrent,$B$6:$C$85,2,FALSE),U15,"")) | X15: - | Y15: 3 | Z15: 8 | AA15: 6 | AB15: 7 | AC15: 1 | AD15: 5 | AE15: - | AF15: 9 | AG15: 1 | AH15: 1 | AI15: 3
B16: 11 | C16: 11 | D16: 1300000 | E16: =IF($C16>VLOOKUP(FurnaceDesired,$B$6:$C$85,2,FALSE),"",IF($C16>VLOOKUP(FurnaceCurrent,$B$6:$C$85,2,FALSE),D16,"")) | F16: 1300000 | G16: =IF($C16>VLOOKUP(FurnaceDesired,$B$6:$C$85,2,FALSE),"",IF($C16>VLOOKUP(FurnaceCurrent,$B$6:$C$85,2,FALSE),F16,"")) | H16: 260000 | I16: =IF($C16>VLOOKUP(FurnaceDesired,$B$6:$C$85,2,FALSE),"",IF($C16>VLOOKUP(FurnaceCurrent,$B$6:$C$85,2,FALSE),H16,"")) | J16: 65000 | K16: =IF($C16>VLOOKUP(FurnaceDesired,$B$6:$C$85,2,FALSE),"",IF($C16>VLOOKUP(FurnaceCurrent,$B$6:$C$85,2,FALSE),J16,"")) | M16: =IF($C16>VLOOKUP(FurnaceDesired,$B$6:$C$85,2,FALSE),"",IF($C16>VLOOKUP(FurnaceCurrent,$B$6:$C$85,2,FALSE),L16,"")) | O16: =IF($C16>VLOOKUP(FurnaceDesired,$B$6:$C$85,2,FALSE),"",IF($C16>VLOOKUP(FurnaceCurrent,$B$6:$C$85,2,FALSE),N16,"")) | R16: 7 | S16: 30 | U16: =T16+S16*60+R16*60*60+Q16*60*60*24 -> 27000 | V16: =IF($C16>VLOOKUP(FurnaceDesired,$B$6:$C$85,2,FALSE),"",IF($C16>VLOOKUP(FurnaceCurrent,$B$6:$C$85,2,FALSE),U16,"")) | X16: - | Y16: 3 | Z16: 10 | AA16: 6 | AB16: 7 | AC16: 1 | AD16: 5 | AE16: 10 | AF16: 9 | AG16: 1 | AH16: 1 | AI16: 3
B17: 12 | C17: 12 | D17: 1600000 | E17: =IF($C17>VLOOKUP(FurnaceDesired,$B$6:$C$85,2,FALSE),"",IF($C17>VLOOKUP(FurnaceCurrent,$B$6:$C$85,2,FALSE),D17,"")) | F17: 1600000 | G17: =IF($C17>VLOOKUP(FurnaceDesired,$B$6:$C$85,2,FALSE),"",IF($C17>VLOOKUP(FurnaceCurrent,$B$6:$C$85,2,FALSE),F17,"")) | H17: 330000 | I17: =IF($C17>VLOOKUP(FurnaceDesired,$B$6:$C$85,2,FALSE),"",IF($C17>VLOOKUP(FurnaceCurrent,$B$6:$C$85,2,FALSE),H17,"")) | J17: 84000 | K17: =IF($C17>VLOOKUP(FurnaceDesired,$B$6:$C$85,2,FALSE),"",IF($C17>VLOOKUP(FurnaceCurrent,$B$6:$C$85,2,FALSE),J17,"")) | M17: =IF($C17>VLOOKUP(FurnaceDesired,$B$6:$C$85,2,FALSE),"",IF($C17>VLOOKUP(FurnaceCurrent,$B$6:$C$85,2,FALSE),L17,"")) | O17: =IF($C17>VLOOKUP(FurnaceDesired,$B$6:$C$85,2,FALSE),"",IF($C17>VLOOKUP(FurnaceCurrent,$B$6:$C$85,2,FALSE),N17,"")) | R17: 9 | U17: =T17+S17*60+R17*60*60+Q17*60*60*24 -> 32400 | V17: =IF($C17>VLOOKUP(FurnaceDesired,$B$6:$C$85,2,FALSE),"",IF($C17>VLOOKUP(FurnaceCurrent,$B$6:$C$85,2,FALSE),U17,"")) | X17: 1 | Y17: 3 | Z17: 11 | AA17: 6 | AB17: 7 | AC17: 1 | AD17: 5 | AE17: 10 | AF17: 9 | AG17: 1 | AH17: 1 | AI17: 3
B18: 13 | C18: 13 | D18: 2300000 | E18: =IF($C18>VLOOKUP(FurnaceDesired,$B$6:$C$85,2,FALSE),"",IF($C18>VLOOKUP(FurnaceCurrent,$B$6:$C$85,2,FALSE),D18,"")) | F18: 2300000 | G18: =IF($C18>VLOOKUP(FurnaceDesired,$B$6:$C$85,2,FALSE),"",IF($C18>VLOOKUP(FurnaceCurrent,$B$6:$C$85,2,FALSE),F18,"")) | H18: 470000 | I18: =IF($C18>VLOOKUP(FurnaceDesired,$B$6:$C$85,2,FALSE),"",IF($C18>VLOOKUP(FurnaceCurrent,$B$6:$C$85,2,FALSE),H18,"")) | J18: 110000 | K18: =IF($C18>VLOOKUP(FurnaceDesired,$B$6:$C$85,2,FALSE),"",IF($C18>VLOOKUP(FurnaceCurrent,$B$6:$C$85,2,FALSE),J18,"")) | M18: =IF($C18>VLOOKUP(FurnaceDesired,$B$6:$C$85,2,FALSE),"",IF($C18>VLOOKUP(FurnaceCurrent,$B$6:$C$85,2,FALSE),L18,"")) | O18: =IF($C18>VLOOKUP(FurnaceDesired,$B$6:$C$85,2,FALSE),"",IF($C18>VLOOKUP(FurnaceCurrent,$B$6:$C$85,2,FALSE),N18,"")) | R18: 11 | U18: =T18+S18*60+R18*60*60+Q18*60*60*24 -> 39600 | V18: =IF($C18>VLOOKUP(FurnaceDesired,$B$6:$C$85,2,FALSE),"",IF($C18>VLOOKUP(FurnaceCurrent,$B$6:$C$85,2,FALSE),U18,"")) | X18: 1 | Y18: 3 | Z18: 12 | AA18: 6 | AB18: 12 | AC18: 1 | AD18: 5 | AE18: 10 | AF18: 9 | AG18: 1 | AH18: 1 | AI18: 3
B19: 14 | C19: 14 | D19: 3100000 | E19: =IF($C19>VLOOKUP(FurnaceDesired,$B$6:$C$85,2,FALSE),"",IF($C19>VLOOKUP(FurnaceCurrent,$B$6:$C$85,2,FALSE),D19,"")) | F19: 3100000 | G19: =IF($C19>VLOOKUP(FurnaceDesired,$B$6:$C$85,2,FALSE),"",IF($C19>VLOOKUP(FurnaceCurrent,$B$6:$C$85,2,FALSE),F19,"")) | H19: 630000 | I19: =IF($C19>VLOOKUP(FurnaceDesired,$B$6:$C$85,2,FALSE),"",IF($C19>VLOOKUP(FurnaceCurrent,$B$6:$C$85,2,FALSE),H19,"")) | J19: 150000 | K19: =IF($C19>VLOOKUP(FurnaceDesired,$B$6:$C$85,2,FALSE),"",IF($C19>VLOOKUP(FurnaceCurrent,$B$6:$C$85,2,FALSE),J19,"")) | M19: =IF($C19>VLOOKUP(FurnaceDesired,$B$6:$C$85,2,FALSE),"",IF($C19>VLOOKUP(FurnaceCurrent,$B$6:$C$85,2,FALSE),L19,"")) | O19: =IF($C19>VLOOKUP(FurnaceDesired,$B$6:$C$85,2,FALSE),"",IF($C19>VLOOKUP(FurnaceCurrent,$B$6:$C$85,2,FALSE),N19,"")) | R19: 14 | U19: =T19+S19*60+R19*60*60+Q19*60*60*24 -> 50400 | V19: =IF($C19>VLOOKUP(FurnaceDesired,$B$6:$C$85,2,FALSE),"",IF($C19>VLOOKUP(FurnaceCurrent,$B$6:$C$85,2,FALSE),U19,"")) | X19: 1 | Y19: 3 | Z19: 13 | AA19: 6 | AB19: 12 | AC19: 1 | AD19: 5 | AE19: 10 | AF19: 13 | AG19: 1 | AH19: 1 | AI19: 3
B20: 15 | C20: 15 | D20: 4600000 | E20: =IF($C20>VLOOKUP(FurnaceDesired,$B$6:$C$85,2,FALSE),"",IF($C20>VLOOKUP(FurnaceCurrent,$B$6:$C$85,2,FALSE),D20,"")) | F20: 4600000 | G20: =IF($C20>VLOOKUP(FurnaceDesired,$B$6:$C$85,2,FALSE),"",IF($C20>VLOOKUP(FurnaceCurrent,$B$6:$C$85,2,FALSE),F20,"")) | H20: 930000 | I20: =IF($C20>VLOOKUP(FurnaceDesired,$B$6:$C$85,2,FALSE),"",IF($C20>VLOOKUP(FurnaceCurrent,$B$6:$C$85,2,FALSE),H20,"")) | J20: 230000 | K20: =IF($C20>VLOOKUP(FurnaceDesired,$B$6:$C$85,2,FALSE),"",IF($C20>VLOOKUP(FurnaceCurrent,$B$6:$C$85,2,FALSE),J20,"")) | M20: =IF($C20>VLOOKUP(FurnaceDesired,$B$6:$C$85,2,FALSE),"",IF($C20>VLOOKUP(FurnaceCurrent,$B$6:$C$85,2,FALSE),L20,"")) | O20: =IF($C20>VLOOKUP(FurnaceDesired,$B$6:$C$85,2,FALSE),"",IF($C20>VLOOKUP(FurnaceCurrent,$B$6:$C$85,2,FALSE),N20,"")) | R20: 18 | U20: =T20+S20*60+R20*60*60+Q20*60*60*24 -> 64800 | V20: =IF($C20>VLOOKUP(FurnaceDesired,$B$6:$C$85,2,FALSE),"",IF($C20>VLOOKUP(FurnaceCurrent,$B$6:$C$85,2,FALSE),U20,"")) | X20: 1 | Y20: 3 | Z20: 14 | AA20: 6 | AB20: 12 | AC20: 1 | AD20: 5 | AE20: 14 | AF20: 13 | AG20: 1 | AH20: 1 | AI20: 3
B21: 16 | C21: 16 | D21: 5900000 | E21: =IF($C21>VLOOKUP(FurnaceDesired,$B$6:$C$85,2,FALSE),"",IF($C21>VLOOKUP(FurnaceCurrent,$B$6:$C$85,2,FALSE),D21,"")) | F21: 5900000 | G21: =IF($C21>VLOOKUP(FurnaceDesired,$B$6:$C$85,2,FALSE),"",IF($C21>VLOOKUP(FurnaceCurrent,$B$6:$C$85,2,FALSE),F21,"")) | H21: 1100000 | I21: =IF($C21>VLOOKUP(FurnaceDesired,$B$6:$C$85,2,FALSE),"",IF($C21>VLOOKUP(FurnaceCurrent,$B$6:$C$85,2,FALSE),H21,"")) | J21: 290000 | K21: =IF($C21>VLOOKUP(FurnaceDesired,$B$6:$C$85,2,FALSE),"",IF($C21>VLOOKUP(FurnaceCurrent,$B$6:$C$85,2,FALSE),J21,"")) | M21: =IF($C21>VLOOKUP(FurnaceDesired,$B$6:$C$85,2,FALSE),"",IF($C21>VLOOKUP(FurnaceCurrent,$B$6:$C$85,2,FALSE),L21,"")) | O21: =IF($C21>VLOOKUP(FurnaceDesired,$B$6:$C$85,2,FALSE),"",IF($C21>VLOOKUP(FurnaceCurrent,$B$6:$C$85,2,FALSE),N21,"")) | Q21: 1 | R21: 6 | S21: 28 | U21: =T21+S21*60+R21*60*60+Q21*60*60*24 -> 109680 | V21: =IF($C21>VLOOKUP(FurnaceDesired,$B$6:$C$85,2,FALSE),"",IF($C21>VLOOKUP(FurnaceCurrent,$B$6:$C$85,2,FALSE),U21,"")) | X21: 1 | Y21: 3 | Z21: 15 | AA21: 6 | AB21: 12 | AC21: 1 | AD21: 5 | AE21: 14 | AF21: 13 | AG21: 15 | AH21: 1 | AI21: 3
B22: 17 | C22: 17 | D22: 9300000 | E22: =IF($C22>VLOOKUP(FurnaceDesired,$B$6:$C$85,2,FALSE),"",IF($C22>VLOOKUP(FurnaceCurrent,$B$6:$C$85,2,FALSE),D22,"")) | F22: 9300000 | G22: =IF($C22>VLOOKUP(FurnaceDesired,$B$6:$C$85,2,FALSE),"",IF($C22>VLOOKUP(FurnaceCurrent,$B$6:$C$85,2,FALSE),F22,"")) | H22: 1800000 | I22: =IF($C22>VLOOKUP(FurnaceDesired,$B$6:$C$85,2,FALSE),"",IF($C22>VLOOKUP(FurnaceCurrent,$B$6:$C$85,2,FALSE),H22,"")) | J22: 460000 | K22: =IF($C22>VLOOKUP(FurnaceDesired,$B$6:$C$85,2,FALSE),"",IF($C22>VLOOKUP(FurnaceCurrent,$B$6:$C$85,2,FALSE),J22,"")) | M22: =IF($C22>VLOOKUP(FurnaceDesired,$B$6:$C$85,2,FALSE),"",IF($C22>VLOOKUP(FurnaceCurrent,$B$6:$C$85,2,FALSE),L22,"")) | O22: =IF($C22>VLOOKUP(FurnaceDesired,$B$6:$C$85,2,FALSE),"",IF($C22>VLOOKUP(FurnaceCurrent,$B$6:$C$85,2,FALSE),N22,"")) | Q22: 1 | R22: 12 | S22: 34 | U22: =T22+S22*60+R22*60*60+Q22*60*60*24 -> 131640 | V22: =IF($C22>VLOOKUP(FurnaceDesired,$B$6:$C$85,2,FALSE),"",IF($C22>VLOOKUP(FurnaceCurrent,$B$6:$C$85,2,FALSE),U22,"")) | X22: 1 | Y22: 3 | Z22: 16 | AA22: 6 | AB22: 16 | AC22: 1 | AD22: 5 | AE22: 14 | AF22: 13 | AG22: 15 | AH22: 1 | AI22: 3
B23: 18 | C23: 18 | D23: 12000000 | E23: =IF($C23>VLOOKUP(FurnaceDesired,$B$6:$C$85,2,FALSE),"",IF($C23>VLOOKUP(FurnaceCurrent,$B$6:$C$85,2,FALSE),D23,"")) | F23: 12000000 | G23: =IF($C23>VLOOKUP(FurnaceDesired,$B$6:$C$85,2,FALSE),"",IF($C23>VLOOKUP(FurnaceCurrent,$B$6:$C$85,2,FALSE),F23,"")) | H23: 2500000 | I23: =IF($C23>VLOOKUP(FurnaceDesired,$B$6:$C$85,2,FALSE),"",IF($C23>VLOOKUP(FurnaceCurrent,$B$6:$C$85,2,FALSE),H23,"")) | J23: 620000 | K23: =IF($C23>VLOOKUP(FurnaceDesired,$B$6:$C$85,2,FALSE),"",IF($C23>VLOOKUP(FurnaceCurrent,$B$6:$C$85,2,FALSE),J23,"")) | M23: =IF($C23>VLOOKUP(FurnaceDesired,$B$6:$C$85,2,FALSE),"",IF($C23>VLOOKUP(FurnaceCurrent,$B$6:$C$85,2,FALSE),L23,"")) | O23: =IF($C23>VLOOKUP(FurnaceDesired,$B$6:$C$85,2,FALSE),"",IF($C23>VLOOKUP(FurnaceCurrent,$B$6:$C$85,2,FALSE),N23,"")) | Q23: 1 | R23: 19 | S23: 53 | U23: =T23+S23*60+R23*60*60+Q23*60*60*24 -> 157980 | V23: =IF($C23>VLOOKUP(FurnaceDesired,$B$6:$C$85,2,FALSE),"",IF($C23>VLOOKUP(FurnaceCurrent,$B$6:$C$85,2,FALSE),U23,"")) | X23: 1 | Y23: 3 | Z23: 17 | AA23: 6 | AB23: 16 | AC23: 1 | AD23: 5 | AE23: 14 | AF23: 17 | AG23: 15 | AH23: 1 | AI23: 3
B24: 19 | C24: 19 | D24: 15000000 | E24: =IF($C24>VLOOKUP(FurnaceDesired,$B$6:$C$85,2,FALSE),"",IF($C24>VLOOKUP(FurnaceCurrent,$B$6:$C$85,2,FALSE),D24,"")) | F24: 15000000 | G24: =IF($C24>VLOOKUP(FurnaceDesired,$B$6:$C$85,2,FALSE),"",IF($C24>VLOOKUP(FurnaceCurrent,$B$6:$C$85,2,FALSE),F24,"")) | H24: 3100000 | I24: =IF($C24>VLOOKUP(FurnaceDesired,$B$6:$C$85,2,FALSE),"",IF($C24>VLOOKUP(FurnaceCurrent,$B$6:$C$85,2,FALSE),H24,"")) | J24: 780000 | K24: =IF($C24>VLOOKUP(FurnaceDesired,$B$6:$C$85,2,FALSE),"",IF($C24>VLOOKUP(FurnaceCurrent,$B$6:$C$85,2,FALSE),J24,"")) | M24: =IF($C24>VLOOKUP(FurnaceDesired,$B$6:$C$85,2,FALSE),"",IF($C24>VLOOKUP(FurnaceCurrent,$B$6:$C$85,2,FALSE),L24,"")) | O24: =IF($C24>VLOOKUP(FurnaceDesired,$B$6:$C$85,2,FALSE),"",IF($C24>VLOOKUP(FurnaceCurrent,$B$6:$C$85,2,FALSE),N24,"")) | Q24: 2 | R24: 17 | S24: 50 | U24: =T24+S24*60+R24*60*60+Q24*60*60*24 -> 237000 | V24: =IF($C24>VLOOKUP(FurnaceDesired,$B$6:$C$85,2,FALSE),"",IF($C24>VLOOKUP(FurnaceCurrent,$B$6:$C$85,2,FALSE),U24,"")) | X24: 1 | Y24: 3 | Z24: 18 | AA24: 6 | AB24: 16 | AC24: 1 | AD24: 5 | AE24: 18 | AF24: 17 | AG24: 15 | AH24: 1 | AI24: 3
B25: 20 | C25: 20 | D25: 21000000 | E25: =IF($C25>VLOOKUP(FurnaceDesired,$B$6:$C$85,2,FALSE),"",IF($C25>VLOOKUP(FurnaceCurrent,$B$6:$C$85,2,FALSE),D25,"")) | F25: 21000000 | G25: =IF($C25>VLOOKUP(FurnaceDesired,$B$6:$C$85,2,FALSE),"",IF($C25>VLOOKUP(FurnaceCurrent,$B$6:$C$85,2,FALSE),F25,"")) | H25: 4300000 | I25: =IF($C25>VLOOKUP(FurnaceDesired,$B$6:$C$85,2,FALSE),"",IF($C25>VLOOKUP(FurnaceCurrent,$B$6:$C$85,2,FALSE),H25,"")) | J25: 1000000 | K25: =IF($C25>VLOOKUP(FurnaceDesired,$B$6:$C$85,2,FALSE),"",IF($C25>VLOOKUP(FurnaceCurrent,$B$6:$C$85,2,FALSE),J25,"")) | M25: =IF($C25>VLOOKUP(FurnaceDesired,$B$6:$C$85,2,FALSE),"",IF($C25>VLOOKUP(FurnaceCurrent,$B$6:$C$85,2,FALSE),L25,"")) | O25: =IF($C25>VLOOKUP(FurnaceDesired,$B$6:$C$85,2,FALSE),"",IF($C25>VLOOKUP(FurnaceCurrent,$B$6:$C$85,2,FALSE),N25,"")) | Q25: 3 | R25: 10 | S25: 18 | U25: =T25+S25*60+R25*60*60+Q25*60*60*24 -> 296280 | V25: =IF($C25>VLOOKUP(FurnaceDesired,$B$6:$C$85,2,FALSE),"",IF($C25>VLOOKUP(FurnaceCurrent,$B$6:$C$85,2,FALSE),U25,"")) | X25: 1 | Y25: 3 | Z25: 19 | AA25: 6 | AB25: 16 | AC25: 1 | AD25: 5 | AE25: 18 | AF25: 17 | AG25: 19 | AH25: 1 | AI25: 3
B26: 21 | C26: 21 | D26: 27000000 | E26: =IF($C26>VLOOKUP(FurnaceDesired,$B$6:$C$85,2,FALSE),"",IF($C26>VLOOKUP(FurnaceCurrent,$B$6:$C$85,2,FALSE),D26,"")) | F26: 27000000 | G26: =IF($C26>VLOOKUP(FurnaceDesired,$B$6:$C$85,2,FALSE),"",IF($C26>VLOOKUP(FurnaceCurrent,$B$6:$C$85,2,FALSE),F26,"")) | H26: 5400000 | I26: =IF($C26>VLOOKUP(FurnaceDesired,$B$6:$C$85,2,FALSE),"",IF($C26>VLOOKUP(FurnaceCurrent,$B$6:$C$85,2,FALSE),H26,"")) | J26: 1300000 | K26: =IF($C26>VLOOKUP(FurnaceDesired,$B$6:$C$85,2,FALSE),"",IF($C26>VLOOKUP(FurnaceCurrent,$B$6:$C$85,2,FALSE),J26,"")) | M26: =IF($C26>VLOOKUP(FurnaceDesired,$B$6:$C$85,2,FALSE),"",IF($C26>VLOOKUP(FurnaceCurrent,$B$6:$C$85,2,FALSE),L26,"")) | O26: =IF($C26>VLOOKUP(FurnaceDesired,$B$6:$C$85,2,FALSE),"",IF($C26>VLOOKUP(FurnaceCurrent,$B$6:$C$85,2,FALSE),N26,"")) | Q26: 4 | R26: 10 | S26: 59 | U26: =T26+S26*60+R26*60*60+Q26*60*60*24 -> 385140 | V26: =IF($C26>VLOOKUP(FurnaceDesired,$B$6:$C$85,2,FALSE),"",IF($C26>VLOOKUP(FurnaceCurrent,$B$6:$C$85,2,FALSE),U26,"")) | X26: 1 | Y26: 3 | Z26: 20 | AA26: 6 | AB26: 20 | AC26: 1 | AD26: 5 | AE26: 18 | AF26: 17 | AG26: 19 | AH26: 1 | AI26: 3
B27: 22 | C27: 22 | D27: 36000000 | E27: =IF($C27>VLOOKUP(FurnaceDesired,$B$6:$C$85,2,FALSE),"",IF($C27>VLOOKUP(FurnaceCurrent,$B$6:$C$85,2,FALSE),D27,"")) | F27: 36000000 | G27: =IF($C27>VLOOKUP(FurnaceDesired,$B$6:$C$85,2,FALSE),"",IF($C27>VLOOKUP(FurnaceCurrent,$B$6:$C$85,2,FALSE),F27,"")) | H27: 7200000 | I27: =IF($C27>VLOOKUP(FurnaceDesired,$B$6:$C$85,2,FALSE),"",IF($C27>VLOOKUP(FurnaceCurrent,$B$6:$C$85,2,FALSE),H27,"")) | J27: 1800000 | K27: =IF($C27>VLOOKUP(FurnaceDesired,$B$6:$C$85,2,FALSE),"",IF($C27>VLOOKUP(FurnaceCurrent,$B$6:$C$85,2,FALSE),J27,"")) | M27: =IF($C27>VLOOKUP(FurnaceDesired,$B$6:$C$85,2,FALSE),"",IF($C27>VLOOKUP(FurnaceCurrent,$B$6:$C$85,2,FALSE),L27,"")) | O27: =IF($C27>VLOOKUP(FurnaceDesired,$B$6:$C$85,2,FALSE),"",IF($C27>VLOOKUP(FurnaceCurrent,$B$6:$C$85,2,FALSE),N27,"")) | Q27: 6 | R27: 16 | S27: 29 | U27: =T27+S27*60+R27*60*60+Q27*60*60*24 -> 577740 | V27: =IF($C27>VLOOKUP(FurnaceDesired,$B$6:$C$85,2,FALSE),"",IF($C27>VLOOKUP(FurnaceCurrent,$B$6:$C$85,2,FALSE),U27,"")) | X27: 1 | Y27: 3 | Z27: 21 | AA27: 6 | AB27: 20 | AC27: 1 | AD27: 5 | AE27: 18 | AF27: 21 | AG27: 19 | AH27: 1 | AI27: 3
B28: 23 | C28: 23 | D28: 44000000 | E28: =IF($C28>VLOOKUP(FurnaceDesired,$B$6:$C$85,2,FALSE),"",IF($C28>VLOOKUP(FurnaceCurrent,$B$6:$C$85,2,FALSE),D28,"")) | F28: 44000000 | G28: =IF($C28>VLOOKUP(FurnaceDesired,$B$6:$C$85,2,FALSE),"",IF($C28>VLOOKUP(FurnaceCurrent,$B$6:$C$85,2,FALSE),F28,"")) | H28: 8900000 | I28: =IF($C28>VLOOKUP(FurnaceDesired,$B$6:$C$85,2,FALSE),"",IF($C28>VLOOKUP(FurnaceCurrent,$B$6:$C$85,2,FALSE),H28,"")) | J28: 2200000 | K28: =IF($C28>VLOOKUP(FurnaceDesired,$B$6:$C$85,2,FALSE),"",IF($C28>VLOOKUP(FurnaceCurrent,$B$6:$C$85,2,FALSE),J28,"")) | M28: =IF($C28>VLOOKUP(FurnaceDesired,$B$6:$C$85,2,FALSE),"",IF($C28>VLOOKUP(FurnaceCurrent,$B$6:$C$85,2,FALSE),L28,"")) | O28: =IF($C28>VLOOKUP(FurnaceDesired,$B$6:$C$85,2,FALSE),"",IF($C28>VLOOKUP(FurnaceCurrent,$B$6:$C$85,2,FALSE),N28,"")) | Q28: 9 | R28: 8 | S28: 40 | U28: =T28+S28*60+R28*60*60+Q28*60*60*24 -> 808800 | V28: =IF($C28>VLOOKUP(FurnaceDesired,$B$6:$C$85,2,FALSE),"",IF($C28>VLOOKUP(FurnaceCurrent,$B$6:$C$85,2,FALSE),U28,"")) | X28: 1 | Y28: 3 | Z28: 22 | AA28: 6 | AB28: 20 | AC28: 1 | AD28: 5 | AE28: 22 | AF28: 21 | AG28: 19 | AH28: 1 | AI28: 3
B29: 24 | C29: 24 | D29: 60000000 | E29: =IF($C29>VLOOKUP(FurnaceDesired,$B$6:$C$85,2,FALSE),"",IF($C29>VLOOKUP(FurnaceCurrent,$B$6:$C$85,2,FALSE),D29,"")) | F29: 60000000 | G29: =IF($C29>VLOOKUP(FurnaceDesired,$B$6:$C$85,2,FALSE),"",IF($C29>VLOOKUP(FurnaceCurrent,$B$6:$C$85,2,FALSE),F29,"")) | H29: 12000000 | I29: =IF($C29>VLOOKUP(FurnaceDesired,$B$6:$C$85,2,FALSE),"",IF($C29>VLOOKUP(FurnaceCurrent,$B$6:$C$85,2,FALSE),H29,"")) | J29: 3000000 | K29: =IF($C29>VLOOKUP(FurnaceDesired,$B$6:$C$85,2,FALSE),"",IF($C29>VLOOKUP(FurnaceCurrent,$B$6:$C$85,2,FALSE),J29,"")) | M29: =IF($C29>VLOOKUP(FurnaceDesired,$B$6:$C$85,2,FALSE),"",IF($C29>VLOOKUP(FurnaceCurrent,$B$6:$C$85,2,FALSE),L29,"")) | O29: =IF($C29>VLOOKUP(FurnaceDesired,$B$6:$C$85,2,FALSE),"",IF($C29>VLOOKUP(FurnaceCurrent,$B$6:$C$85,2,FALSE),N29,"")) | Q29: 13 | R29: 2 | S29: 33 | U29: =T29+S29*60+R29*60*60+Q29*60*60*24 -> 1132380 | V29: =IF($C29>VLOOKUP(FurnaceDesired,$B$6:$C$85,2,FALSE),"",IF($C29>VLOOKUP(FurnaceCurrent,$B$6:$C$85,2,FALSE),U29,"")) | X29: 1 | Y29: 3 | Z29: 23 | AA29: 6 | AB29: 20 | AC29: 1 | AD29: 5 | AE29: 22 | AF29: 21 | AG29: 23 | AH29: 1 | AI29: 3
B30: 25 | C30: 25 | D30: 81000000 | E30: =IF($C30>VLOOKUP(FurnaceDesired,$B$6:$C$85,2,FALSE),"",IF($C30>VLOOKUP(FurnaceCurrent,$B$6:$C$85,2,FALSE),D30,"")) | F30: 81000000 | G30: =IF($C30>VLOOKUP(FurnaceDesired,$B$6:$C$85,2,FALSE),"",IF($C30>VLOOKUP(FurnaceCurrent,$B$6:$C$85,2,FALSE),F30,"")) | H30: 16000000 | I30: =IF($C30>VLOOKUP(FurnaceDesired,$B$6:$C$85,2,FALSE),"",IF($C30>VLOOKUP(FurnaceCurrent,$B$6:$C$85,2,FALSE),H30,"")) | J30: 4000000 | K30: =IF($C30>VLOOKUP(FurnaceDesired,$B$6:$C$85,2,FALSE),"",IF($C30>VLOOKUP(FurnaceCurrent,$B$6:$C$85,2,FALSE),J30,"")) | M30: =IF($C30>VLOOKUP(FurnaceDesired,$B$6:$C$85,2,FALSE),"",IF($C30>VLOOKUP(FurnaceCurrent,$B$6:$C$85,2,FALSE),L30,"")) | O30: =IF($C30>VLOOKUP(FurnaceDesired,$B$6:$C$85,2,FALSE),"",IF($C30>VLOOKUP(FurnaceCurrent,$B$6:$C$85,2,FALSE),N30,"")) | Q30: 18 | R30: 8 | S30: 22 | U30: =T30+S30*60+R30*60*60+Q30*60*60*24 -> 1585320 | V30: =IF($C30>VLOOKUP(FurnaceDesired,$B$6:$C$85,2,FALSE),"",IF($C30>VLOOKUP(FurnaceCurrent,$B$6:$C$85,2,FALSE),U30,"")) | X30: 1 | Y30: 3 | Z30: 24 | AA30: 6 | AB30: 24 | AC30: 1 | AD30: 5 | AE30: 22 | AF30: 21 | AG30: 23 | AH30: 1 | AI30: 3
B31: 26 | C31: 26 | D31: 100000000 | E31: =IF($C31>VLOOKUP(FurnaceDesired,$B$6:$C$85,2,FALSE),"",IF($C31>VLOOKUP(FurnaceCurrent,$B$6:$C$85,2,FALSE),D31,"")) | F31: 100000000 | G31: =IF($C31>VLOOKUP(FurnaceDesired,$B$6:$C$85,2,FALSE),"",IF($C31>VLOOKUP(FurnaceCurrent,$B$6:$C$85,2,FALSE),F31,"")) | H31: 21000000 | I31: =IF($C31>VLOOKUP(FurnaceDesired,$B$6:$C$85,2,FALSE),"",IF($C31>VLOOKUP(FurnaceCurrent,$B$6:$C$85,2,FALSE),H31,"")) | J31: 5200000 | K31: =IF($C31>VLOOKUP(FurnaceDesired,$B$6:$C$85,2,FALSE),"",IF($C31>VLOOKUP(FurnaceCurrent,$B$6:$C$85,2,FALSE),J31,"")) | M31: =IF($C31>VLOOKUP(FurnaceDesired,$B$6:$C$85,2,FALSE),"",IF($C31>VLOOKUP(FurnaceCurrent,$B$6:$C$85,2,FALSE),L31,"")) | O31: =IF($C31>VLOOKUP(FurnaceDesired,$B$6:$C$85,2,FALSE),"",IF($C31>VLOOKUP(FurnaceCurrent,$B$6:$C$85,2,FALSE),N31,"")) | Q31: 21 | R31: 2 | S31: 26 | U31: =T31+S31*60+R31*60*60+Q31*60*60*24 -> 1823160 | V31: =IF($C31>VLOOKUP(FurnaceDesired,$B$6:$C$85,2,FALSE),"",IF($C31>VLOOKUP(FurnaceCurrent,$B$6:$C$85,2,FALSE),U31,"")) | X31: 1 | Y31: 3 | Z31: 25 | AA31: 6 | AB31: 24 | AC31: 1 | AD31: 5 | AE31: 22 | AF31: 25 | AG31: 23 | AH31: 1 | AI31: 3
B32: 27 | C32: 27 | D32: 140000000 | E32: =IF($C32>VLOOKUP(FurnaceDesired,$B$6:$C$85,2,FALSE),"",IF($C32>VLOOKUP(FurnaceCurrent,$B$6:$C$85,2,FALSE),D32,"")) | F32: 140000000 | G32: =IF($C32>VLOOKUP(FurnaceDesired,$B$6:$C$85,2,FALSE),"",IF($C32>VLOOKUP(FurnaceCurrent,$B$6:$C$85,2,FALSE),F32,"")) | H32: 24000000 | I32: =IF($C32>VLOOKUP(FurnaceDesired,$B$6:$C$85,2,FALSE),"",IF($C32>VLOOKUP(FurnaceCurrent,$B$6:$C$85,2,FALSE),H32,"")) | J32: 7400000 | K32: =IF($C32>VLOOKUP(FurnaceDesired,$B$6:$C$85,2,FALSE),"",IF($C32>VLOOKUP(FurnaceCurrent,$B$6:$C$85,2,FALSE),J32,"")) | M32: =IF($C32>VLOOKUP(FurnaceDesired,$B$6:$C$85,2,FALSE),"",IF($C32>VLOOKUP(FurnaceCurrent,$B$6:$C$85,2,FALSE),L32,"")) | O32: =IF($C32>VLOOKUP(FurnaceDesired,$B$6:$C$85,2,FALSE),"",IF($C32>VLOOKUP(FurnaceCurrent,$B$6:$C$85,2,FALSE),N32,"")) | Q32: 25 | R32: 7 | S32: 43 | U32: =T32+S32*60+R32*60*60+Q32*60*60*24 -> 2187780 | V32: =IF($C32>VLOOKUP(FurnaceDesired,$B$6:$C$85,2,FALSE),"",IF($C32>VLOOKUP(FurnaceCurrent,$B$6:$C$85,2,FALSE),U32,"")) | X32: 1 | Y32: 3 | Z32: 26 | AA32: 6 | AB32: 24 | AC32: 1 | AD32: 5 | AE32: 26 | AF32: 25 | AG32: 23 | AH32: 1 | AI32: 3
... B35: 30 | C35: 30 | D35: 300000000 | E35: =IF($C35>VLOOKUP(FurnaceDesired,$B$6:$C$85,2,FALSE),"",IF($C35>VLOOKUP(FurnaceCurrent,$B$6:$C$85,2,FALSE),D35,"")) | F35: 300000000 | G35: =IF($C35>VLOOKUP(FurnaceDesired,$B$6:$C$85,2,FALSE),"",IF($C35>VLOOKUP(FurnaceCurrent,$B$6:$C$85,2,FALSE),F35,"")) | H35: 60000000 | I35: =IF($C35>VLOOKUP(FurnaceDesired,$B$6:$C$85,2,FALSE),"",IF($C35>VLOOKUP(FurnaceCurrent,$B$6:$C$85,2,FALSE),H35,"")) | J35: 15000000 | K35: =IF($C35>VLOOKUP(FurnaceDesired,$B$6:$C$85,2,FALSE),"",IF($C35>VLOOKUP(FurnaceCurrent,$B$6:$C$85,2,FALSE),J35,"")) | M35: =IF($C35>VLOOKUP(FurnaceDesired,$B$6:$C$85,2,FALSE),"",IF($C35>VLOOKUP(FurnaceCurrent,$B$6:$C$85,2,FALSE),L35,"")) | O35: =IF($C35>VLOOKUP(FurnaceDesired,$B$6:$C$85,2,FALSE),"",IF($C35>VLOOKUP(FurnaceCurrent,$B$6:$C$85,2,FALSE),N35,"")) | Q35: 40 | R35: 4 | S35: 27 | U35: =T35+S35*60+R35*60*60+Q35*60*60*24 -> 3472020 | V35: =IF($C35>VLOOKUP(FurnaceDesired,$B$6:$C$85,2,FALSE),"",IF($C35>VLOOKUP(FurnaceCurrent,$B$6:$C$85,2,FALSE),U35,"")) | X35: 1 | Y35: 3 | Z35: 29 | AA35: 6 | AB35: 28 | AC35: 1 | AD35: 5 | AE35: 26 | AF35: 29 | AG35: 27 | AH35: 1 | AI35: 3
B36: 30-1 | C36: 31 | D36: 67000000 | E36: =IF($C36>VLOOKUP(FurnaceDesired,$B$6:$C$85,2,FALSE),"",IF($C36>VLOOKUP(FurnaceCurrent,$B$6:$C$85,2,FALSE),D36,"")) | F36: 67000000 | G36: =IF($C36>VLOOKUP(FurnaceDesired,$B$6:$C$85,2,FALSE),"",IF($C36>VLOOKUP(FurnaceCurrent,$B$6:$C$85,2,FALSE),F36,"")) | H36: 13000000 | I36: =IF($C36>VLOOKUP(FurnaceDesired,$B$6:$C$85,2,FALSE),"",IF($C36>VLOOKUP(FurnaceCurrent,$B$6:$C$85,2,FALSE),H36,"")) | J36: 3300000 | K36: =IF($C36>VLOOKUP(FurnaceDesired,$B$6:$C$85,2,FALSE),"",IF($C36>VLOOKUP(FurnaceCurrent,$B$6:$C$85,2,FALSE),J36,"")) | L36: 132 | M36: =IF($C36>VLOOKUP(FurnaceDesired,$B$6:$C$85,2,FALSE),"",IF($C36>VLOOKUP(FurnaceCurrent,$B$6:$C$85,2,FALSE),L36,"")) | O36: =IF($C36>VLOOKUP(FurnaceDesired,$B$6:$C$85,2,FALSE),"",IF($C36>VLOOKUP(FurnaceCurrent,$B$6:$C$85,2,FALSE),N36,"")) | Q36: 7 | U36: =T36+S36*60+R36*60*60+Q36*60*60*24 -> 604800 | V36: =IF($C36>VLOOKUP(FurnaceDesired,$B$6:$C$85,2,FALSE),"",IF($C36>VLOOKUP(FurnaceCurrent,$B$6:$C$85,2,FALSE),U36,"")) | X36: 1 | Y36: 3 | Z36: 30 | AA36: 6 | AB36: 28 | AC36: 1 | AD36: 5 | AE36: 26 | AF36: 29 | AG36: 30 | AH36: 1 | AI36: 3
B37: 30-2 | C37: 32 | D37: 67000000 | E37: =IF($C37>VLOOKUP(FurnaceDesired,$B$6:$C$85,2,FALSE),"",IF($C37>VLOOKUP(FurnaceCurrent,$B$6:$C$85,2,FALSE),D37,"")) | F37: 67000000 | G37: =IF($C37>VLOOKUP(FurnaceDesired,$B$6:$C$85,2,FALSE),"",IF($C37>VLOOKUP(FurnaceCurrent,$B$6:$C$85,2,FALSE),F37,"")) | H37: 13000000 | I37: =IF($C37>VLOOKUP(FurnaceDesired,$B$6:$C$85,2,FALSE),"",IF($C37>VLOOKUP(FurnaceCurrent,$B$6:$C$85,2,FALSE),H37,"")) | J37: 3300000 | K37: =IF($C37>VLOOKUP(FurnaceDesired,$B$6:$C$85,2,FALSE),"",IF($C37>VLOOKUP(FurnaceCurrent,$B$6:$C$85,2,FALSE),J37,"")) | L37: 132 | M37: =IF($C37>VLOOKUP(FurnaceDesired,$B$6:$C$85,2,FALSE),"",IF($C37>VLOOKUP(FurnaceCurrent,$B$6:$C$85,2,FALSE),L37,"")) | O37: =IF($C37>VLOOKUP(FurnaceDesired,$B$6:$C$85,2,FALSE),"",IF($C37>VLOOKUP(FurnaceCurrent,$B$6:$C$85,2,FALSE),N37,"")) | Q37: 7 | U37: =T37+S37*60+R37*60*60+Q37*60*60*24 -> 604800 | V37: =IF($C37>VLOOKUP(FurnaceDesired,$B$6:$C$85,2,FALSE),"",IF($C37>VLOOKUP(FurnaceCurrent,$B$6:$C$85,2,FALSE),U37,"")) | X37: 1 | Y37: 3 | Z37: 30 | AA37: 6 | AB37: 28 | AC37: 1 | AD37: 5 | AE37: 26 | AF37: 29 | AG37: 30 | AH37: 1 | AI37: 3
B38: 30-3 | C38: 33 | D38: 67000000 | E38: =IF($C38>VLOOKUP(FurnaceDesired,$B$6:$C$85,2,FALSE),"",IF($C38>VLOOKUP(FurnaceCurrent,$B$6:$C$85,2,FALSE),D38,"")) | F38: 67000000 | G38: =IF($C38>VLOOKUP(FurnaceDesired,$B$6:$C$85,2,FALSE),"",IF($C38>VLOOKUP(FurnaceCurrent,$B$6:$C$85,2,FALSE),F38,"")) | H38: 13000000 | I38: =IF($C38>VLOOKUP(FurnaceDesired,$B$6:$C$85,2,FALSE),"",IF($C38>VLOOKUP(FurnaceCurrent,$B$6:$C$85,2,FALSE),H38,"")) | J38: 3300000 | K38: =IF($C38>VLOOKUP(FurnaceDesired,$B$6:$C$85,2,FALSE),"",IF($C38>VLOOKUP(FurnaceCurrent,$B$6:$C$85,2,FALSE),J38,"")) | L38: 132 | M38: =IF($C38>VLOOKUP(FurnaceDesired,$B$6:$C$85,2,FALSE),"",IF($C38>VLOOKUP(FurnaceCurrent,$B$6:$C$85,2,FALSE),L38,"")) | O38: =IF($C38>VLOOKUP(FurnaceDesired,$B$6:$C$85,2,FALSE),"",IF($C38>VLOOKUP(FurnaceCurrent,$B$6:$C$85,2,FALSE),N38,"")) | Q38: 7 | U38: =T38+S38*60+R38*60*60+Q38*60*60*24 -> 604800 | V38: =IF($C38>VLOOKUP(FurnaceDesired,$B$6:$C$85,2,FALSE),"",IF($C38>VLOOKUP(FurnaceCurrent,$B$6:$C$85,2,FALSE),U38,"")) | X38: 1 | Y38: 3 | Z38: 30 | AA38: 6 | AB38: 28 | AC38: 1 | AD38: 5 | AE38: 26 | AF38: 29 | AG38: 30 | AH38: 1 | AI38: 3
B39: 30-4 | C39: 34 | D39: 67000000 | E39: =IF($C39>VLOOKUP(FurnaceDesired,$B$6:$C$85,2,FALSE),"",IF($C39>VLOOKUP(FurnaceCurrent,$B$6:$C$85,2,FALSE),D39,"")) | F39: 67000000 | G39: =IF($C39>VLOOKUP(FurnaceDesired,$B$6:$C$85,2,FALSE),"",IF($C39>VLOOKUP(FurnaceCurrent,$B$6:$C$85,2,FALSE),F39,"")) | H39: 13000000 | I39: =IF($C39>VLOOKUP(FurnaceDesired,$B$6:$C$85,2,FALSE),"",IF($C39>VLOOKUP(FurnaceCurrent,$B$6:$C$85,2,FALSE),H39,"")) | J39: 3300000 | K39: =IF($C39>VLOOKUP(FurnaceDesired,$B$6:$C$85,2,FALSE),"",IF($C39>VLOOKUP(FurnaceCurrent,$B$6:$C$85,2,FALSE),J39,"")) | L39: 132 | M39: =IF($C39>VLOOKUP(FurnaceDesired,$B$6:$C$85,2,FALSE),"",IF($C39>VLOOKUP(FurnaceCurrent,$B$6:$C$85,2,FALSE),L39,"")) | O39: =IF($C39>VLOOKUP(FurnaceDesired,$B$6:$C$85,2,FALSE),"",IF($C39>VLOOKUP(FurnaceCurrent,$B$6:$C$85,2,FALSE),N39,"")) | Q39: 7 | U39: =T39+S39*60+R39*60*60+Q39*60*60*24 -> 604800 | V39: =IF($C39>VLOOKUP(FurnaceDesired,$B$6:$C$85,2,FALSE),"",IF($C39>VLOOKUP(FurnaceCurrent,$B$6:$C$85,2,FALSE),U39,"")) | X39: 1 | Y39: 3 | Z39: 30 | AA39: 6 | AB39: 28 | AC39: 1 | AD39: 5 | AE39: 26 | AF39: 29 | AG39: 30 | AH39: 1 | AI39: 3
B40: FC1 | C40: 35 | D40: 67000000 | E40: =IF($C40>VLOOKUP(FurnaceDesired,$B$6:$C$85,2,FALSE),"",IF($C40>VLOOKUP(FurnaceCurrent,$B$6:$C$85,2,FALSE),D40,"")) | F40: 67000000 | G40: =IF($C40>VLOOKUP(FurnaceDesired,$B$6:$C$85,2,FALSE),"",IF($C40>VLOOKUP(FurnaceCurrent,$B$6:$C$85,2,FALSE),F40,"")) | H40: 13000000 | I40: =IF($C40>VLOOKUP(FurnaceDesired,$B$6:$C$85,2,FALSE),"",IF($C40>VLOOKUP(FurnaceCurrent,$B$6:$C$85,2,FALSE),H40,"")) | J40: 3300000 | K40: =IF($C40>VLOOKUP(FurnaceDesired,$B$6:$C$85,2,FALSE),"",IF($C40>VLOOKUP(FurnaceCurrent,$B$6:$C$85,2,FALSE),J40,"")) | L40: 132 | M40: =IF($C40>VLOOKUP(FurnaceDesired,$B$6:$C$85,2,FALSE),"",IF($C40>VLOOKUP(FurnaceCurrent,$B$6:$C$85,2,FALSE),L40,"")) | O40: =IF($C40>VLOOKUP(FurnaceDesired,$B$6:$C$85,2,FALSE),"",IF($C40>VLOOKUP(FurnaceCurrent,$B$6:$C$85,2,FALSE),N40,"")) | Q40: 7 | U40: =T40+S40*60+R40*60*60+Q40*60*60*24 -> 604800 | V40: =IF($C40>VLOOKUP(FurnaceDesired,$B$6:$C$85,2,FALSE),"",IF($C40>VLOOKUP(FurnaceCurrent,$B$6:$C$85,2,FALSE),U40,"")) | X40: 1 | Y40: 3 | Z40: 30 | AA40: 6 | AB40: 28 | AC40: 1 | AD40: 5 | AE40: 26 | AF40: 29 | AG40: 30 | AH40: 1 | AI40: 3
B41: FC1-1 | C41: 36 | D41: 72000000 | E41: =IF($C41>VLOOKUP(FurnaceDesired,$B$6:$C$85,2,FALSE),"",IF($C41>VLOOKUP(FurnaceCurrent,$B$6:$C$85,2,FALSE),D41,"")) | F41: 72000000 | G41: =IF($C41>VLOOKUP(FurnaceDesired,$B$6:$C$85,2,FALSE),"",IF($C41>VLOOKUP(FurnaceCurrent,$B$6:$C$85,2,FALSE),F41,"")) | H41: 14000000 | I41: =IF($C41>VLOOKUP(FurnaceDesired,$B$6:$C$85,2,FALSE),"",IF($C41>VLOOKUP(FurnaceCurrent,$B$6:$C$85,2,FALSE),H41,"")) | J41: 3600000 | K41: =IF($C41>VLOOKUP(FurnaceDesired,$B$6:$C$85,2,FALSE),"",IF($C41>VLOOKUP(FurnaceCurrent,$B$6:$C$85,2,FALSE),J41,"")) | L41: 158 | M41: =IF($C41>VLOOKUP(FurnaceDesired,$B$6:$C$85,2,FALSE),"",IF($C41>VLOOKUP(FurnaceCurrent,$B$6:$C$85,2,FALSE),L41,"")) | O41: =IF($C41>VLOOKUP(FurnaceDesired,$B$6:$C$85,2,FALSE),"",IF($C41>VLOOKUP(FurnaceCurrent,$B$6:$C$85,2,FALSE),N41,"")) | Q41: 9 | U41: =T41+S41*60+R41*60*60+Q41*60*60*24 -> 777600 | V41: =IF($C41>VLOOKUP(FurnaceDesired,$B$6:$C$85,2,FALSE),"",IF($C41>VLOOKUP(FurnaceCurrent,$B$6:$C$85,2,FALSE),U41,"")) | X41: 1 | Y41: 3 | Z41: FC1 | AA41: 6 | AB41: 28 | AC41: 1 | AD41: 5 | AE41: FC1 | AF41: 29 | AG41: 30 | AH41: 1 | AI41: 3
B42: FC1-2 | C42: 37 | D42: 72000000 | E42: =IF($C42>VLOOKUP(FurnaceDesired,$B$6:$C$85,2,FALSE),"",IF($C42>VLOOKUP(FurnaceCurrent,$B$6:$C$85,2,FALSE),D42,"")) | F42: 72000000 | G42: =IF($C42>VLOOKUP(FurnaceDesired,$B$6:$C$85,2,FALSE),"",IF($C42>VLOOKUP(FurnaceCurrent,$B$6:$C$85,2,FALSE),F42,"")) | H42: 14000000 | I42: =IF($C42>VLOOKUP(FurnaceDesired,$B$6:$C$85,2,FALSE),"",IF($C42>VLOOKUP(FurnaceCurrent,$B$6:$C$85,2,FALSE),H42,"")) | J42: 3600000 | K42: =IF($C42>VLOOKUP(FurnaceDesired,$B$6:$C$85,2,FALSE),"",IF($C42>VLOOKUP(FurnaceCurrent,$B$6:$C$85,2,FALSE),J42,"")) | L42: 158 | M42: =IF($C42>VLOOKUP(FurnaceDesired,$B$6:$C$85,2,FALSE),"",IF($C42>VLOOKUP(FurnaceCurrent,$B$6:$C$85,2,FALSE),L42,"")) | O42: =IF($C42>VLOOKUP(FurnaceDesired,$B$6:$C$85,2,FALSE),"",IF($C42>VLOOKUP(FurnaceCurrent,$B$6:$C$85,2,FALSE),N42,"")) | Q42: 9 | U42: =T42+S42*60+R42*60*60+Q42*60*60*24 -> 777600 | V42: =IF($C42>VLOOKUP(FurnaceDesired,$B$6:$C$85,2,FALSE),"",IF($C42>VLOOKUP(FurnaceCurrent,$B$6:$C$85,2,FALSE),U42,"")) | X42: 1 | Y42: 3 | Z42: FC1 | AA42: 6 | AB42: 28 | AC42: 1 | AD42: 5 | AE42: FC1 | AF42: 29 | AG42: 30 | AH42: 1 | AI42: 3
B43: FC1-3 | C43: 38 | D43: 72000000 | E43: =IF($C43>VLOOKUP(FurnaceDesired,$B$6:$C$85,2,FALSE),"",IF($C43>VLOOKUP(FurnaceCurrent,$B$6:$C$85,2,FALSE),D43,"")) | F43: 72000000 | G43: =IF($C43>VLOOKUP(FurnaceDesired,$B$6:$C$85,2,FALSE),"",IF($C43>VLOOKUP(FurnaceCurrent,$B$6:$C$85,2,FALSE),F43,"")) | H43: 14000000 | I43: =IF($C43>VLOOKUP(FurnaceDesired,$B$6:$C$85,2,FALSE),"",IF($C43>VLOOKUP(FurnaceCurrent,$B$6:$C$85,2,FALSE),H43,"")) | J43: 3600000 | K43: =IF($C43>VLOOKUP(FurnaceDesired,$B$6:$C$85,2,FALSE),"",IF($C43>VLOOKUP(FurnaceCurrent,$B$6:$C$85,2,FALSE),J43,"")) | L43: 158 | M43: =IF($C43>VLOOKUP(FurnaceDesired,$B$6:$C$85,2,FALSE),"",IF($C43>VLOOKUP(FurnaceCurrent,$B$6:$C$85,2,FALSE),L43,"")) | O43: =IF($C43>VLOOKUP(FurnaceDesired,$B$6:$C$85,2,FALSE),"",IF($C43>VLOOKUP(FurnaceCurrent,$B$6:$C$85,2,FALSE),N43,"")) | Q43: 9 | U43: =T43+S43*60+R43*60*60+Q43*60*60*24 -> 777600 | V43: =IF($C43>VLOOKUP(FurnaceDesired,$B$6:$C$85,2,FALSE),"",IF($C43>VLOOKUP(FurnaceCurrent,$B$6:$C$85,2,FALSE),U43,"")) | X43: 1 | Y43: 3 | Z43: FC1 | AA43: 6 | AB43: 28 | AC43: 1 | AD43: 5 | AE43: FC1 | AF43: 29 | AG43: 30 | AH43: 1 | AI43: 3
...

Sheet Chief Gear & Charms
A1: (631) Zerethusta's Whiteout Survival Chief Gear & Charms Calculator
C5: Chief Gear Items | L5: Chief Charm Items
C6: Hardened Alloy | E6: Polishing Solution | G6: Design Plans | I6: Lunar Amber | L6: Charm Guides | N6: Charm Designs | P6: Charm Secrets
C7: 2000000 | E7: 15000 | G7: 3000 | I7: 150 | L7: 9000 | N7: 7500 | P7: 750
B9: Hat (Lancer) | O9: Watch (Lancer)
B10: Chief Gear | O10: Chief Gear
B11: Current | D11: Desired | O11: Current | Q11: Desired
B12: Mythic | D12: Mythic T1 | O12: Mythic | Q12: Mythic T1
C13: Charms | O13: Charms | U13: Uncommon
C14: Left | D14: Top | E14: Right | O14: Left | P14: Top | Q14: Right | U14: Rare
C15: Current | D15: Current | E15: Current | O15: Current | P15: Current | Q15: Current | U15: Epic
C16: 12 | D16: 12 | E16: 12 | O16: 12 | P16: 12 | Q16: 12 | U16: Mythic
C17: Desired | D17: Desired | E17: Desired | O17: Desired | P17: Desired | Q17: Desired | U17: Legendary
C18: 13 | D18: 13 | E18: 13
B19: Coat (Infantry) | O19: Pants (Infantry)
B20: Chief Gear | O20: Chief Gear
B21: Current | D21: Desired | O21: Current | Q21: Desired
B22: Mythic T1 | D22: Mythic T2 | O22: Legendary T3 (3-Star) | Q22: Legendary T4 (3-Star)
C23: Charms | O23: Charms
C24: Left | D24: Top | E24: Right | O24: Left | P24: Top | Q24: Right
C25: Current | D25: Current | E25: Current | O25: Current | P25: Current | Q25: Current
C26: 14 | D26: 14 | E26: 14 | O26: 14 | P26: 14 | Q26: 14
C27: Desired | D27: Desired | E27: Desired | O27: Desired | P27: Desired | Q27: Desired | T27: Chief Gear upgrades to T4 have been added, but are missing the SVS points. I will add when I find the data.
C28: 15 | D28: 15 | E28: 15 | O28: 15 | P28: 15 | Q28: 15
B29: Ring (Marksman) | O29: Cudgel (Marksman)
B30: Chief Gear | O30: Chief Gear
B31: Current | D31: Desired | O31: Current | Q31: Desired
B32: Mythic | D32: Mythic T2 | O32: Mythic | Q32: Mythic T2
C33: Charms | O33: Charms
C34: Left | D34: Top | E34: Right | O34: Left | P34: Top | Q34: Right | T34: Chief Power Gains
C35: Current | D35: Current | E35: Current | O35: Current | P35: Current | Q35: Current | T35: Gear | V35: Charms
C36: 13 | D36: 13 | E36: 13 | O36: 13 | P36: 13 | Q36: 13 | S36: Current | T36: ='New Chief Gear Data'!J125 -> 10730400 | V36: ='Charms Data'!K41 -> 31536000
C37: Desired | D37: Desired | E37: Desired | O37: Desired | P37: Desired | Q37: Desired | S37: Desired | T37: ='New Chief Gear Data'!K125 -> 13260000 | V37: =SUM('Charms Data'!L23:L40) -> 34776000
C38: 14 | D38: 14 | E38: 14 | O38: 14 | P38: 14 | Q38: 14 | S38: Increase | T38: =IFERROR(IF(T37>T36,T37-T36,"-"),"-") -> 2529600 | V38: =IFERROR(IF(V37>V36,V37-V36,"-"),"-") -> 3240000
S39: SVS Points | T39: ='New Chief Gear Data'!L125 -> 8523000 | V39: ='Charms Data'!M41*70 -> 20160000
C40: Chief Items Needed For Desired Upgrades
C41: Chief Gear | G41: Charms | K41: Chief Items from Exchange and Chests
C42: Hardened Alloy | D42: Polishing Solution | E42: Design Plans | F42: Lunar Amber | G42: Charm Guides | H42: Charm Designs | I42: Charm Secrets | K42: Enhancement Material Exchange | Q42: War Chant Custom Chests | W42: Chief Charm Material Exchange
L43: Excess Design Plans | N43: =E48 -> 490 | Q43: Quantity | S43: 287 | T43: Remaining | U43: =S43-SUM(T45:T47) -> 287 | W43: Exchange | Y43: Guides | Z43: Designs | AA43: Secrets | AB43: Notes
B44: Cost | C44: ='New Chief Gear Data'!F125 -> 1417000 | D44: ='New Chief Gear Data'!G125 -> 15030 | E44: ='New Chief Gear Data'!H125 -> 2510 | F44: ='New Chief Gear Data'!I125 -> 160 | G44: =NeededCharmGuides -> 8940 | H44: =NeededCharmDesigns -> 7350 | I44: =NeededCharmSecrets -> 780 | K44: Exchange For | M44: Multiplier | N44: Quantity | O44: Total | Q44: Contents | S44: Multiplier | T44: Quantity | U44: Total | W44: 2 Guides = 1 Design | Z44: =Y44/2 -> 0 | AB44: Max 500
...

Sheet New Chief Gear Data
D3: Gear Level | E3: # | F3: Alloy | G3: Polish | H3: Plans | I3: Amber | J3: Power | K3: SvS Points
D4: Locked | E4: 1 | F4: 0 | G4: 0 | H4: 0 | I4: 0 | J4: 0 | K4: 0 | L4: Locked
B5: Uncommon | D5: Uncommon | E5: 2 | F5: 1500 | G5: 15 | H5: 0 | I5: 0 | J5: 224400 | K5: 1125 | L5: Uncommon
B6: Rare | D6: Uncommon (1-Star) | E6: 3 | F6: 3800 | G6: 40 | H6: 0 | I6: 0 | J6: 306000 | K6: 1875 | L6: Uncommon (1-Star)
B7: Epic | D7: Rare | E7: 4 | F7: 7000 | G7: 70 | H7: 0 | I7: 0 | J7: 408000 | K7: 3000 | L7: Rare
B8: Mythic | D8: Rare (1-Star) | E8: 5 | F8: 9700 | G8: 95 | H8: 0 | I8: 0 | J8: 510000 | K8: 4500 | L8: Rare (1-Star)
B9: Legendary | D9: Rare (2-Star) | E9: 6 | F9: 0 | G9: 0 | H9: 45 | I9: 0 | J9: 612000 | K9: 5100 | L9: Rare (2-Star)
D10: Rare (3-Star) | E10: 7 | F10: 0 | G10: 0 | H10: 50 | I10: 0 | J10: 714000 | K10: 5440 | L10: Rare (3-Star)
D11: Epic | E11: 8 | F11: 0 | G11: 0 | H11: 60 | I11: 0 | J11: 816000 | K11: 3230 | L11: Epic
D12: Epic (1-Star) | E12: 9 | F12: 0 | G12: 0 | H12: 70 | I12: 0 | J12: 885360 | K12: 3230 | L12: Epic (1-Star)
D13: Epic (2-Star) | E13: 10 | F13: 6500 | G13: 65 | H13: 40 | I13: 0 | J13: 954720 | K13: 3225 | L13: Epic (2-Star)
D14: Epic (3-Star) | E14: 11 | F14: 8000 | G14: 80 | H14: 50 | I14: 0 | J14: 1024080 | K14: 3225 | L14: Epic (3-Star)
D15: Epic T1 | E15: 12 | F15: 10000 | G15: 95 | H15: 60 | I15: 0 | J15: 1093440 | K15: 3440 | L15: Epic T1
D16: Epic T1 (1-Star) | E16: 13 | F16: 11000 | G16: 110 | H16: 70 | I16: 0 | J16: 1162800 | K16: 3440 | L16: Epic T1 (1-Star)
D17: Epic T1 (2-Star) | E17: 14 | F17: 13000 | G17: 130 | H17: 85 | I17: 0 | J17: 1232160 | K17: 4085 | L17: Epic T1 (2-Star)
D18: Epic T1 (3-Star) | E18: 15 | F18: 15000 | G18: 160 | H18: 100 | I18: 0 | J18: 1301520 | K18: 4085 | L18: Epic T1 (3-Star)
D19: Mythic | E19: 16 | F19: 22000 | G19: 220 | H19: 40 | I19: 0 | J19: 1362720 | K19: 6250 | L19: Mythic
D20: Mythic (1-Star) | E20: 17 | F20: 23000 | G20: 230 | H20: 40 | I20: 0 | J20: 1423920 | K20: 6250 | L20: Mythic (1-Star)
D21: Mythic (2-Star) | E21: 18 | F21: 25000 | G21: 250 | H21: 45 | I21: 0 | J21: 1485120 | K21: 6250 | L21: Mythic (2-Star)
... D31: Mythic T2 (3-Star Status: 1) | E31: 28 | F31: 12500 | G31: 132 | H31: 21 | I31: 2 | J31: 2065500 | K31: 2320 | L31: Mythic T2 (3-Star Status: 1)
